Workbook
Name 支払先リスト: 支払先リスト!$A$1:$A$36014

Sheet 取引先別実績一覧
A1: 111期保守費支払（取引先一覧）
A3: 取引先コード | B3: 取引先名 | D3: 処理 | E3: =実績!D1 -> 2020年4月度 | F3: 件数
A4: GB552 | B4: (株)ＰＦＵ 関西支店 | D4: ＥＤＩ | E4: =VLOOKUP(B4,実績!$E$5:$I$56,5,0) -> 0 | F4: =VLOOKUP(B4,実績!$E$5:$H$56,4,0) -> -
A5: GB547 | B5: (株)瑞穂 | D5: ＥＤＩ | E5: =VLOOKUP(B5,実績!$E$5:$I$56,5,0) -> 0 | F5: =VLOOKUP(B5,実績!$E$5:$H$56,4,0) -> -
A6: EB303 | B6: ソフラ(株) | D6: ＥＤＩ | E6: =VLOOKUP(B6,実績!$E$5:$I$56,5,0) -> 0 | F6: =VLOOKUP(B6,実績!$E$5:$H$56,4,0) -> -
A7: EB615 | B7: (株)アルゴグラフィックス | D7: ＥＤＩ | E7: =VLOOKUP(B7,実績!$E$5:$I$56,5,0) -> 0 | F7: =VLOOKUP(B7,実績!$E$5:$H$56,4,0) -> -
A8: FM294 | B8: (株)フルノシステムズ | D8: ＥＤＩ | E8: =VLOOKUP(B8,実績!$E$5:$I$56,5,0) -> 0 | F8: =VLOOKUP(B8,実績!$E$5:$H$56,4,0) -> -
A9: FL734 | B9: (株)光アルファクス | D9: ＥＤＩ | E9: =VLOOKUP(B9,実績!$E$5:$I$56,5,0) -> 0 | F9: =VLOOKUP(B9,実績!$E$5:$H$56,4,0) -> -
A10: EG100 | B10: オリックスレンテック株式会社 | D10: ＥＤＩ | E10: =VLOOKUP(B10,実績!$E$5:$I$56,5,0) -> 0 | F10: =VLOOKUP(B10,実績!$E$5:$H$56,4,0) -> -
A11: EQ506 | B11: (株)サトー | D11: ＥＤＩ | E11: =VLOOKUP(B11,実績!$E$5:$I$56,5,0) -> 0 | F11: =VLOOKUP(B11,実績!$E$5:$H$56,4,0) -> -
A12: FK305 | B12: 萩原テクノソリューションズ株式会社 | D12: ＥＤＩ | E12: =VLOOKUP(B12,実績!$E$5:$I$56,5,0) -> 0 | F12: =VLOOKUP(B12,実績!$E$5:$H$56,4,0) -> -
A13: GD484 | B13: メディカル・コンピュータ・サービス(株) | D13: ＥＤＩ | E13: =VLOOKUP(B13,実績!$E$5:$I$56,5,0) -> 0 | F13: =VLOOKUP(B13,実績!$E$5:$H$56,4,0) -> -
A14: GA801 | B14: パシフィックシステム株式会社 | D14: ＥＤＩ | E14: =VLOOKUP(B14,実績!$E$5:$I$56,5,0) -> 0 | F14: =VLOOKUP(B14,実績!$E$5:$H$56,4,0) -> -
A15: FB015 | B15: デル・テクノロジーズ株式会社 | D15: ＥＤＩ | E15: =VLOOKUP(B15,実績!$E$5:$I$56,5,0) -> 0 | F15: =VLOOKUP(B15,実績!$E$5:$H$56,4,0) -> -
... A22: EB833 | B22: 株式会社アイオイ・システム | D22: ＥＤＩ | E22: =VLOOKUP(B22,実績!$E$5:$I$56,5,0) -> 0 | F22: =VLOOKUP(B22,実績!$E$5:$H$56,4,0) -> -
A23: GK688 | B23: 椿本興業株式会社 | D23: ＥＤＩ | E23: =VLOOKUP(B23,実績!$E$5:$I$56,5,0) -> 0 | F23: =VLOOKUP(B23,実績!$E$5:$H$56,4,0) -> - | G23: ※2024/5/13～EDI稼働（請求書：A781P⇒ EDI：GK688へ変更）
A24: GG518 | B24: 株式会社ゼネラルＢＲＥＸＡテクノロジー | D24: ＥＤＩ | E24: =VLOOKUP(B24,実績!$E$5:$I$56,5,0) -> 0 | G24: ※2026/4月～追加
A25: GB504 | B25: (株)イシダ | D25: 注文書 | E25: =VLOOKUP(B25,実績!$E$5:$I$56,5,0) -> 0 | F25: =VLOOKUP(B25,実績!$E$5:$H$56,4,0) -> -
A26: EK774 | B26: キヤノンマーケティングジャパン株式会社 | D26: 注文書 | E26: =VLOOKUP(B26,実績!$E$5:$I$56,5,0) -> 0 | F26: =VLOOKUP(B26,実績!$E$5:$H$56,4,0) -> -
A27: ED039 | B27: 伊藤忠テクノソリューションズ(株) | D27: 注文書 | E27: =VLOOKUP(B27,実績!$E$5:$I$56,5,0) -> 0 | F27: =VLOOKUP(B27,実績!$E$5:$H$56,4,0) -> -
A28: GK326 | B28: 株式会社NTTデータ | D28: 注文書 | E28: =VLOOKUP(B28,実績!$E$5:$I$56,5,0) -> 0 | F28: =VLOOKUP(B28,実績!$E$5:$H$56,4,0) -> -
A29: GG518 | B29: (株)富士通ｾﾞﾈﾗﾙ情報ｼｽﾃﾑ | D29: 注文書 | E29: =VLOOKUP(B29,実績!$E$5:$I$56,5,0) -> 0 | F29: =VLOOKUP(B29,実績!$E$5:$H$56,4,0) -> -
A30: ED709 | B30: IDEC AUTO-ID SOLUTIONS株式会社 | D30: 注文書 | E30: =VLOOKUP(B30,実績!$E$5:$I$56,5,0) -> 0 | F30: =VLOOKUP(B30,実績!$E$5:$H$56,4,0) -> -
A31: FA619 | B31: 株式会社寺岡精工 | D31: 注文書 | E31: =VLOOKUP(B31,実績!$E$5:$I$56,5,0) -> 0 | F31: =VLOOKUP(B31,実績!$E$5:$H$56,4,0) -> -
A32: AAY17 | B32: 株式会社日立インダストリアルプロダクツ | D32: 中 | E32: =VLOOKUP(B32,実績!$E$5:$I$56,5,0) -> 0 | F32: =VLOOKUP(B32,実績!$E$5:$H$56,4,0) -> - | G32: 旧：日立製作所
A33: W0307 | B33: (株)シーネット | D33: 中 | E33: =VLOOKUP(B33,実績!$E$5:$I$56,5,0) -> 0 | F33: =VLOOKUP(B33,実績!$E$5:$H$56,4,0) -> -
A34: A217R | B34: 株式会社リコー | D34: 末 | E34: =VLOOKUP(B34,実績!$E$5:$I$56,5,0) -> 0 | F34: =VLOOKUP(B34,実績!$E$5:$H$56,4,0) -> - | G34: ←2025.1月～追加 | I34: 中締OR末締不明
A35: B2328 | B35: エプソン販売(株) | D35: 末 | E35: =VLOOKUP(B35,実績!$E$5:$I$56,5,0) -> 0 | F35: =VLOOKUP(B35,実績!$E$5:$H$56,4,0) -> -
A36: A465A | B36: ロジスティードソリューションズ株式会社 | D36: 末 | E36: =VLOOKUP(B36,実績!$E$5:$I$56,5,0) -> 0 | F36: =VLOOKUP(B36,実績!$E$5:$H$56,4,0) -> -
A37: A020D | B37: 日本ハネウェル株式会社 | D37: 中 | E37: =VLOOKUP(B37,実績!$E$5:$I$56,5,0) -> 0 | F37: =VLOOKUP(B37,実績!$E$5:$H$56,4,0) -> -
A38: A0281 | B38: 都築電気株式会社 | D38: 末 | E38: =VLOOKUP(B38,実績!$E$5:$I$56,5,0) -> 0 | F38: =VLOOKUP(B38,実績!$E$5:$H$56,4,0) -> -
A39: D2221 | B39: 株式会社大塚商会 | D39: 末 | E39: =VLOOKUP(B39,実績!$E$5:$I$56,5,0) -> 0 | F39: =VLOOKUP(B39,実績!$E$5:$H$56,4,0) -> -
A40: D1881 | B40: イーソル株式会社 | D40: 末 | E40: =VLOOKUP(B40,実績!$E$5:$I$56,5,0) -> 0 | F40: =VLOOKUP(B40,実績!$E$5:$H$56,4,0) -> -
A41: L0147 | B41: 三谷産業株式会社 | D41: 末 | E41: =VLOOKUP(B41,実績!$E$5:$I$56,5,0) -> 0 | F41: =VLOOKUP(B41,実績!$E$5:$H$56,4,0) -> -
A42: A963L | B42: 株式会社タクテック | D42: 末 | E42: =VLOOKUP(B42,実績!$E$5:$I$56,5,0) -> 0 | F42: =VLOOKUP(B42,実績!$E$5:$H$56,4,0) -> -
A43: A048P | B43: キンドリルジャパン株式会社 | D43: 中 | E43: =VLOOKUP(B43,実績!$E$5:$I$56,5,0) -> 0 | F43: =VLOOKUP(B43,実績!$E$5:$H$56,4,0) -> -
A44: A572Q | B44: 株式会社Mujin Japan | D44: 末 | E44: =VLOOKUP(B44,実績!$E$5:$I$56,5,0) -> 0 | F44: =VLOOKUP(B44,実績!$E$5:$H$56,4,0) -> -
A45: A879R | B45: エトリア株式会社 | D45: - | G45: ←2026.1月～追加 | I45: 中締OR末締不明
B46: 株式会社日立オートメーション | D46: - | G46: ←2026.2月～追加 | I46: 中締OR末締不明
B47: 合計 | E47: =SUM(E4:E44) -> 0 | F47: =SUM(F4:F44) -> 0
...

Sheet 実績
D1: 2020年4月度 | G1: 発注一覧 | M1: ↓納品書 | O1: ↓事前発注分
D3: NO | E3: 取引先名 | F3: 発注予定 | H3: 検収実績 | K3: 発注 | L3: 検収
F4: 件数 | G4: 支払金額 | H4: 件数 | I4: 支払金額（税抜） | J4: 支払金額（税込）
C5: EDI | D5: 1 | E5: (株)ＰＦＵ 関西支店 | F5: =COUNTIF(支払一覧!$F$4:$F$1434,実績!$E5) -> 0 | G5: =SUMIF(支払一覧!$F$4:$F$3000,実績!$E5,支払一覧!$I$4:$I$3000) -> 0 | H5: =IF(F5=0,"-","★") -> -
D6: 2 | E6: (株)瑞穂 | F6: =COUNTIF(支払一覧!$F$4:$F$1434,実績!$E6) -> 0 | G6: =SUMIF(支払一覧!$F$4:$F$3000,実績!$E6,支払一覧!$I$4:$I$3000) -> 0 | H6: =IF(F6=0,"-","★") -> -
D7: 3 | E7: ソフラ(株) | F7: =COUNTIF(支払一覧!$F$4:$F$1434,実績!$E7) -> 0 | G7: =SUMIF(支払一覧!$F$4:$F$3000,実績!$E7,支払一覧!$I$4:$I$3000) -> 0 | H7: =IF(F7=0,"-","★") -> -
D8: 4 | E8: (株)アルゴグラフィックス | F8: =COUNTIF(支払一覧!$F$4:$F$1434,実績!$E8) -> 0 | G8: =SUMIF(支払一覧!$F$4:$F$3000,実績!$E8,支払一覧!$I$4:$I$3000) -> 0 | H8: =IF(F8=0,"-","★") -> -
D9: 5 | E9: (株)フルノシステムズ | F9: =COUNTIF(支払一覧!$F$4:$F$1434,実績!$E9) -> 0 | G9: =SUMIF(支払一覧!$F$4:$F$3000,実績!$E9,支払一覧!$I$4:$I$3000) -> 0 | H9: =IF(F9=0,"-","★") -> -
D10: 6 | E10: (株)光アルファクス | F10: =COUNTIF(支払一覧!$F$4:$F$1434,実績!$E10) -> 0 | G10: =SUMIF(支払一覧!$F$4:$F$3000,実績!$E10,支払一覧!$I$4:$I$3000) -> 0 | H10: =IF(F10=0,"-","★") -> -
D11: 7 | E11: オリックスレンテック株式会社 | F11: =COUNTIF(支払一覧!$F$4:$F$1434,実績!$E11) -> 0 | G11: =SUMIF(支払一覧!$F$4:$F$3000,実績!$E11,支払一覧!$I$4:$I$3000) -> 0 | H11: =IF(F11=0,"-","★") -> -
D12: 8 | E12: (株)サトー | F12: =COUNTIF(支払一覧!$F$4:$F$1434,実績!$E12) -> 0 | G12: =SUMIF(支払一覧!$F$4:$F$3000,実績!$E12,支払一覧!$I$4:$I$3000) -> 0 | H12: =IF(F12=0,"-","★") -> -
D13: 9 | E13: 萩原テクノソリューションズ株式会社 | F13: =COUNTIF(支払一覧!$F$4:$F$1434,実績!$E13) -> 0 | G13: =SUMIF(支払一覧!$F$4:$F$3000,実績!$E13,支払一覧!$I$4:$I$3000) -> 0 | H13: =IF(F13=0,"-","★") -> -
D14: 10 | E14: メディカル・コンピュータ・サービス(株) | F14: =COUNTIF(支払一覧!$F$4:$F$1434,実績!$E14) -> 0 | G14: =SUMIF(支払一覧!$F$4:$F$3000,実績!$E14,支払一覧!$I$4:$I$3000) -> 0 | H14: =IF(F14=0,"-","★") -> -
D15: 11 | E15: パシフィックシステム株式会社 | F15: =COUNTIF(支払一覧!$F$4:$F$1434,実績!$E15) -> 0 | G15: =SUMIF(支払一覧!$F$4:$F$3000,実績!$E15,支払一覧!$I$4:$I$3000) -> 0 | H15: =IF(F15=0,"-","★") -> -
D16: 12 | E16: デル・テクノロジーズ株式会社 | F16: =COUNTIF(支払一覧!$F$4:$F$1434,実績!$E16) -> 0 | G16: =SUMIF(支払一覧!$F$4:$F$3000,実績!$E16,支払一覧!$I$4:$I$3000) -> 0 | H16: =IF(F16=0,"-","★") -> -
D17: 13 | E17: ホクショー(株) | F17: =COUNTIF(支払一覧!$F$4:$F$1434,実績!$E17) -> 0 | G17: =SUMIF(支払一覧!$F$4:$F$3000,実績!$E17,支払一覧!$I$4:$I$3000) -> 0 | H17: =IF(F17=0,"-","★") -> - | R17: NXNPﾛｼﾞ分はMCMにデータない為、予定にデータ追加する
D18: 14 | E18: (株)コンテック | F18: =COUNTIF(支払一覧!$F$4:$F$1434,実績!$E18) -> 0 | G18: =SUMIF(支払一覧!$F$4:$F$3000,実績!$E18,支払一覧!$I$4:$I$3000) -> 0 | H18: =IF(F18=0,"-","★") -> - | R18: MCMにデータない為、予定にデータ追加する。
D19: 15 | E19: 三菱電機デジタルイノベーション株式会社 | F19: =COUNTIF(支払一覧!$F$4:$F$1434,実績!$E19) -> 0 | G19: =SUMIF(支払一覧!$F$4:$F$3000,実績!$E19,支払一覧!$I$4:$I$3000) -> 0 | H19: =IF(F19=0,"-","★") -> -
D20: 16 | E20: 東芝テック株式会社 | F20: =COUNTIF(支払一覧!$F$4:$F$1434,実績!$E20) -> 0 | G20: =SUMIF(支払一覧!$F$4:$F$3000,実績!$E20,支払一覧!$I$4:$I$3000) -> 0 | H20: =IF(F20=0,"-","★") -> -
D21: 17 | E21: ジック株式会社 | F21: =COUNTIF(支払一覧!$F$4:$F$1434,実績!$E21) -> 0 | G21: =SUMIF(支払一覧!$F$4:$F$3000,実績!$E21,支払一覧!$I$4:$I$3000) -> 0 | H21: =IF(F21=0,"-","★") -> -
D22: 18 | E22: 株式会社立花エレテック | F22: =COUNTIF(支払一覧!$F$4:$F$1434,実績!$E22) -> 0 | G22: =SUMIF(支払一覧!$F$4:$F$3000,実績!$E22,支払一覧!$I$4:$I$3000) -> 0 | H22: =IF(F22=0,"-","★") -> -
D23: 19 | E23: 株式会社アイオイ・システム | F23: =COUNTIF(支払一覧!$F$4:$F$1434,実績!$E23) -> 0 | G23: =SUMIF(支払一覧!$F$4:$F$3000,実績!$E23,支払一覧!$I$4:$I$3000) -> 0 | H23: =IF(F23=0,"-","★") -> -
D24: 20 | E24: 椿本興業株式会社 | F24: =COUNTIF(支払一覧!$F$4:$F$1434,実績!$E24) -> 0 | G24: =SUMIF(支払一覧!$F$4:$F$3000,実績!$E24,支払一覧!$I$4:$I$3000) -> 0 | H24: =IF(F24=0,"-","★") -> -
D25: 21 | E25: 株式会社ゼネラルＢＲＥＸＡテクノロジー | F25: =COUNTIF(支払一覧!$F$4:$F$1434,実績!$E25) -> 0 | G25: =SUMIF(支払一覧!$F$4:$F$3000,実績!$E25,支払一覧!$I$4:$I$3000) -> 0 | H25: =IF(F25=0,"-","★") -> - | N25: ←2026/4月～追加
E26: 小計_A | F26: =SUM(F5:F24) -> 0 | G26: =SUM(G5:G24) -> 0 | H26: =SUM(H5:H24) -> 0 | I26: =SUM(I5:I24) -> 0
M27: ↓注文書
C28: 非EDI | D28: 1 | E28: (株)イシダ | F28: =COUNTIF(支払一覧!$F$4:$F$1434,実績!$E28) -> 0 | G28: =SUMIF(支払一覧!$F$4:$F$3000,実績!$E28,支払一覧!$I$4:$I$3000) -> 0 | H28: =IF(F28=0,"-","★") -> -
D29: 2 | E29: キヤノンマーケティングジャパン株式会社 | F29: =COUNTIF(支払一覧!$F$4:$F$1434,実績!$E29) -> 0 | G29: =SUMIF(支払一覧!$F$4:$F$3000,実績!$E29,支払一覧!$I$4:$I$3000) -> 0 | H29: =IF(F29=0,"-","★") -> -
D30: 3 | E30: 伊藤忠テクノソリューションズ(株) | F30: =COUNTIF(支払一覧!$F$4:$F$1434,実績!$E30) -> 0 | G30: =SUMIF(支払一覧!$F$4:$F$3000,実績!$E30,支払一覧!$I$4:$I$3000) -> 0 | H30: =IF(F30=0,"-","★") -> -
D31: 4 | E31: 株式会社NTTデータ | F31: =COUNTIF(支払一覧!$F$4:$F$1434,実績!$E31) -> 0 | G31: =SUMIF(支払一覧!$F$4:$F$3000,実績!$E31,支払一覧!$I$4:$I$3000) -> 0 | H31: =IF(F31=0,"-","★") -> -
D32: 5 | E32: (株)富士通ｾﾞﾈﾗﾙ情報ｼｽﾃﾑ | F32: =COUNTIF(支払一覧!$F$4:$F$1434,実績!$E32) -> 0 | G32: =SUMIF(支払一覧!$F$4:$F$3000,実績!$E32,支払一覧!$I$4:$I$3000) -> 0 | H32: =IF(F32=0,"-","★") -> -
D33: 6 | E33: IDEC AUTO-ID SOLUTIONS株式会社 | F33: =COUNTIF(支払一覧!$F$4:$F$1434,実績!$E33) -> 0 | G33: =SUMIF(支払一覧!$F$4:$F$3000,実績!$E33,支払一覧!$I$4:$I$3000) -> 0 | H33: =IF(F33=0,"-","★") -> -
D34: 7 | E34: 株式会社寺岡精工 | F34: =COUNTIF(支払一覧!$F$4:$F$1434,実績!$E34) -> 0 | G34: =SUMIF(支払一覧!$F$4:$F$3000,実績!$E34,支払一覧!$I$4:$I$3000) -> 0 | H34: =IF(F34=0,"-","★") -> -
E35: 小計_B | F35: =SUM(F28:F34) -> 0 | G35: =SUM(G28:G34) -> 0 | H35: =SUM(H28:H34) -> 0 | I35: =SUM(I28:I34) -> 0
E36: 注文書合計（Ａ+Ｂ） | F36: =SUM(F26+F35) -> 0 | G36: =SUM(G26+G35) -> 0 | H36: =SUM(H26+H35) -> 0 | I36: =SUM(I26+I35) -> 0 | L36: 処理
C37: 請求書 | D37: 1 | E37: (株)シーネット | F37: =COUNTIF(支払一覧!$F$4:$F$1434,実績!$E37) -> 0 | G37: =SUMIF(支払一覧!$F$4:$F$3000,実績!$E37,支払一覧!$I$4:$I$3000) -> 0 | H37: =IF(F37=0,"-","★") -> - | J37: =I37*1.1 -> 0 | K37: 中締め
D38: 2 | E38: 株式会社リコー | F38: =COUNTIF(支払一覧!$F$4:$F$1434,実績!$E38) -> 0 | G38: =SUMIF(支払一覧!$F$4:$F$3000,実績!$E38,支払一覧!$I$4:$I$3000) -> 0 | H38: =IF(F38=0,"-","★") -> - | J38: =I38*1.1 -> 0 | M38: ←2025.1月～追加 | O38: 中締OR末締不明
D39: 3 | E39: エプソン販売(株) | F39: =COUNTIF(支払一覧!$F$4:$F$1434,実績!$E39) -> 0 | G39: =SUMIF(支払一覧!$F$4:$F$3000,実績!$E39,支払一覧!$I$4:$I$3000) -> 0 | H39: =IF(F39=0,"-","★") -> - | J39: =I39*1.1 -> 0
D40: 4 | E40: 株式会社日立インダストリアルプロダクツ | F40: =COUNTIF(支払一覧!$F$4:$F$1434,実績!$E40) -> 0 | G40: =SUMIF(支払一覧!$F$4:$F$3000,実績!$E40,支払一覧!$I$4:$I$3000) -> 0 | H40: =IF(F40=0,"-","★") -> - | J40: =I40*1.1 -> 0
D41: 5 | E41: ロジスティードソリューションズ株式会社 | F41: =COUNTIF(支払一覧!$F$4:$F$1434,実績!$E41) -> 0 | G41: =SUMIF(支払一覧!$F$4:$F$3000,実績!$E41,支払一覧!$I$4:$I$3000) -> 0 | H41: =IF(F41=0,"-","★") -> - | J41: =I41*1.1 -> 0
...

Sheet 支払不要
H1: 合計 | I1: =SUM(I4:I9) -> 0
H2: 件数 | I2: =COUNT(I4:I15) -> 0
A3: NO. | B3: CSﾅﾝﾊﾞ | C3: 納入先名 | D3: 店舗名 | E3: 契約書No | F3: 取引先名 | G3: 支払回数 | H3: 支払月 | I3: 支払金額 | J3: 製番 | K3: 支払コード | L3: 支払方法 | M3: 製番 | N3: 照合 | O3: チェック

Sheet 支払一覧
H1: 合計 | I1: =SUBTOTAL(9,I4:I63421) -> 0
H2: 件数 | I2: =SUBTOTAL(2,A4:A63421) -> 0
A3: NO. | B3: CSﾅﾝﾊﾞ | C3: 納入先名 | D3: 店舗名 | E3: 契約書No | F3: 取引先名 | G3: 支払回数 | H3: 支払月 | I3: 支払金額 | J3: 製番 | K3: 支払コード | L3: 支払方法 | M3: 製番 | N3: 照合 | O3: チェック

Sheet 印刷用
A1: 43622 | C1: 支払明細書：(株)ＰＦＵ 関西支店 【EDI】コード：GB552
H2: 合計 | J2: =SUBTOTAL(9,H7:H65536) -> 0
H3: 件数 | J3: =SUBTOTAL(2,A7:A65536) -> 4
H4: 税込み | J4: =J2*1.1 -> 0
A6: NO. | B6: CSﾅﾝﾊﾞ | C6: 店舗名 | D6: 支払月 | E6: 取引先名 | F6: 契約書No | G6: 納入先名 | H6: 支払金額 | I6: 支払回数 | J6: 製番 | K6: 支払コード | L6: 支払方法
A7: 1 | B7: =支払一覧!B4 -> 0 | C7: =支払一覧!D4 -> 0 | D7: =支払一覧!H4 -> 0 | E7: =支払一覧!F4 -> 0 | F7: =支払一覧!E4 -> 0 | G7: =支払一覧!C4 -> 0 | H7: =支払一覧!I4 -> 0 | I7: =支払一覧!G4 -> 0 | J7: =支払一覧!J4 -> 0 | K7: =支払一覧!K4 -> 0 | L7: =支払一覧!L4 -> 0
A8: 2 | B8: =支払一覧!B5 -> 0 | C8: =支払一覧!D5 -> 0 | D8: =支払一覧!H5 -> 0 | E8: =支払一覧!F5 -> 0 | F8: =支払一覧!E5 -> 0 | G8: =支払一覧!C5 -> 0 | H8: =支払一覧!I5 -> 0 | I8: =支払一覧!G5 -> 0 | J8: =支払一覧!J5 -> 0 | K8: =支払一覧!K5 -> 0 | L8: =支払一覧!L5 -> 0
A9: 3 | B9: =支払一覧!B6 -> 0 | C9: =支払一覧!D6 -> 0 | D9: =支払一覧!H6 -> 0 | E9: =支払一覧!F6 -> 0 | F9: =支払一覧!E6 -> 0 | G9: =支払一覧!C6 -> 0 | H9: =支払一覧!I6 -> 0 | I9: =支払一覧!G6 -> 0 | J9: =支払一覧!J6 -> 0 | K9: =支払一覧!K6 -> 0 | L9: =支払一覧!L6 -> 0
A10: 4 | B10: =支払一覧!B7 -> 0 | C10: =支払一覧!D7 -> 0 | D10: =支払一覧!H7 -> 0 | E10: =支払一覧!F7 -> 0 | F10: =支払一覧!E7 -> 0 | G10: =支払一覧!C7 -> 0 | H10: =支払一覧!I7 -> 0 | I10: =支払一覧!G7 -> 0 | J10: =支払一覧!J7 -> 0 | K10: =支払一覧!K7 -> 0 | L10: =支払一覧!L7 -> 0

Sheet バッチ
N4: 金額合計⇒ | O4: =SUBTOTAL(9,$K$8:$K$2450) -> 0
N5: 件数⇒ | O5: =SUBTOTAL(2,$K$8:$K$2450) -> 0
A7: テキスト（全角30文字） | B7: 文字数 | C7: NO. | D7: CSﾅﾝﾊﾞ | E7: 納入先名 | F7: 店舗名 | G7: 契約書No | H7: 取引先名 | I7: 支払回数 | J7: 支払月 | K7: 支払金額 | L7: 保守製番 | M7: 支払コード | N7: 支払方法

Sheet バッチリスト
A1: No. | B1: 仕入先＊ 半角5桁 | C1: 注区＊ | D1: 購買発注日付＊ YYYYMMDD形式 | E1: 納入日付＊ YYYYMMDD形式 | F1: 購買組織＊ 半角4桁 | G1: 購買グループ＊ （発注担当） 半角3桁 | H1: プラント＊ （工場） 半角4桁 | I1: 保管場所 （倉庫） 半角4桁 | J1: WBS 要素＊ （製番） 半角12桁 | K1: 図面追番 半角5桁(数字) | L1: 品目コード （品番） 半角14桁 | M1: 品目コード２ （品番） 半角14桁 | N1: 品目欄№ 半角5桁(数字) | O1: テキスト (短)＊ （品名） 全角30文字 | P1: 型式 半角25文字 | Q1: 購買発注量＊ | R1: 発注単位＊ 半角2桁 | S1: 正味価格＊ | T1: 価格単位＊ | U1: 品目グループ＊ （口座） 半角3桁 | V1: 売上税コード＊ 半角2桁
B2: 必要 | C2: 固定 | D2: 必要 | E2: 必要 | F2: 固定 | G2: 固定 | H2: 固定 | J2: 必要 | K2: 不要 | O2: 必要 | P2: 不要 | Q2: 固定 | R2: 固定 | S2: 必要 | T2: 固定 | U2: 固定 | V2: 固定
B3: ① | C3: 1 | D3: ② | E3: ③ | F3: z100 | G3: 0WH | H3: A230 | J3: ④ | O3: ⑤ | Q3: 1 | R3: PC | S3: ⑥ | T3: 1 | U3: LFD | V3: V3
A4: ①バッチよりNO.コピー、A6セル以降に貼り付け ②B～V列6行以降コピー | C4: 1 | D4: 20190617 | E4: 20190628 | F4: z100 | G4: 0WH | H4: A230 | Q4: 1 | R4: PC | T4: 1 | U4: LFD | V4: V3
A5: NO. | B5: 支払コード | D5: TODAY | J5: 保守製番 | O5: テキスト（全角30文字） | S5: 支払金額
A6: 1 | B6: =バッチ!M8 -> 0 | C6: =$C$4 -> 1 | D6: =$D$4 -> 20190617 | E6: =$E$4 -> 20190628 | F6: =$F$4 -> z100 | G6: =$G$4 -> 0WH | H6: =$H$4 -> A230 | J6: =バッチ!L8 -> 0 | O6: =バッチ!A8 -> 0 | Q6: =$Q$4 -> 1 | R6: =$R$4 -> PC | S6: =バッチ!K8 -> 0 | T6: =$T$4 -> 1 | U6: =$U$4 -> LFD | V6: V3

Sheet 支払先リスト
A1: 支払明細書：(株)ＰＦＵ 関西支店 【EDI】コード：GB552 | B1: (株)ＰＦＵ 関西支店 | C1: GB552 | D1: EDI | G1: 取引先マスタのフラグ↓
A2: 支払明細書：(株)瑞穂 【EDI】コード：GB547 | B2: (株)瑞穂 | C2: GB547 | D2: EDI | G2: EDI | H2: 1：国内仕入先（EDI）
A3: 支払明細書：ソフラ(株) 【EDI】コード：EB303 | B3: ソフラ(株) | C3: EB303 | D3: EDI | G3: 注文書 | H3: 3：支払通知書（EDI）
A4: 支払明細書：(株)アルゴグラフィックス 【EDI】コード：EB615 | B4: (株)アルゴグラフィックス | C4: EB615 | D4: EDI | G4: 注文書 | H4: 支払通知書（郵送）
A5: 支払明細書：(株)フルノシステムズ 【EDI】コード：FM294 | B5: (株)フルノシステムズ | C5: FM294 | D5: EDI | G5: 請求書 | H5: 支払通知書（郵送）
A6: 支払明細書：(株)光アルファクス 【EDI】コード：FL734 | B6: (株)光アルファクス | C6: FL734 | D6: EDI
A7: 支払明細書：オリックスレンテック(株) 【EDI】コード：EG100 | B7: オリックスレンテック株式会社 | C7: EG100 | D7: EDI
A8: 支払明細書：(株)サトー 【EDI】コード：EQ506 | B8: (株)サトー | C8: EQ506 | D8: EDI
A9: 支払明細書：萩原テクノソリューションズ(株) 【EDI】コード：FK305 | B9: 萩原テクノソリューションズ株式会社 | C9: FK305 | D9: EDI
A10: 支払明細書：メディカル・コンピュータ・サービス(株) 【EDI】コード：GD484 | B10: メディカル・コンピュータ・サービス(株) | C10: GD484 | D10: EDI
A11: 支払明細書：パシフィックシステム(株) 【EDI】コード：GA801 | B11: パシフィックシステム株式会社 | C11: GA801 | D11: EDI
A12: 支払明細書：(株)NTTデータ ■【注文書】コード：GK326 G/L勘定：66150040 | B12: 株式会社NTTデータ | C12: GK326 | D12: 注文書
A13: 支払明細書：デル・テクノロジーズ(株) 【EDI】コード：FB015 | B13: デル・テクノロジーズ株式会社 | C13: FB015 | D13: EDI
A14: 支払明細書：ホクショー(株) 【EDI】コード：FP391 | B14: ホクショー(株) | C14: FP391 | D14: EDI
A15: 支払明細書：(株)コンテック 【EDI】コード：EM586 | B15: (株)コンテック | C15: EM586 | D15: EDI
A16: 支払明細書：三菱電機デジタルイノベーション(株) 【EDI】コード：GJ190 | B16: 三菱電機デジタルイノベーション株式会社 | C16: GJ190 | D16: EDI
A17: 支払明細書：東芝テック(株) 【EDI】コード：FB496 | B17: 東芝テック株式会社 | C17: FB496 | D17: EDI
... A20: 支払明細書：(株)アイオイ・システム 【EDI】コード：EB833 | B20: 株式会社アイオイ・システム | C20: EB833 | D20: EDI
A21: 支払明細書：(株)CSIソリューションズ ■【注文書】コード：GE285 | B21: (株)CSIｿﾘｭｰｼｮﾝｽﾞ | C21: GE285 | D21: 注文書 | E21: 削除フラグ | F21: A351E | G21: 請求書
A22: 支払明細書：NTTデータ先端技術(株) ■【注文書】コード：GA377 | B22: NTTﾃﾞｰﾀ先端技術(株) | C22: GA377 | D22: 注文書 | E22: 削除フラグ
A23: 支払明細書：(株)アトムエンジニアリング ■【注文書】コード：EB143 | B23: (株)アトムエンジニアリング | C23: EB143 | D23: 注文書 | E23: 削除フラグ
A24: 支払明細書：(株)イシダ ■【注文書】コード：GB504 | B24: (株)イシダ | C24: GB504 | D24: 注文書
A25: 支払明細書：キヤノンマーケティングジャパン(株) ■【注文書】コード：EK774 | B25: キヤノンマーケティングジャパン株式会社 | C25: EK774 | D25: 注文書
A26: 支払明細書：リコージャパン(株) ■【注文書】コード：EA249 | B26: リコージャパン(株) | C26: EA249 | D26: 注文書
A27: 支払明細書：伊藤忠テクノソリューションズ(株) ■【注文書】コード：ED039 | B27: 伊藤忠テクノソリューションズ(株) | C27: ED039 | D27: 注文書 | E27: 削除フラグ | F27: B1399 | G27: 納品書
A28: 支払明細書：日本アイ・ビー・エム(株) ■【注文書】コード：FF943 | B28: 日本アイ・ビー・エム(株) | C28: FF943 | D28: 注文書 | E28: 削除フラグ | G28: 請求書で数件コードあり（銀行口座不一致）
A29: 支払明細書：パシフィックシステム(株) ■【注文書】コード：GA801 | B29: パシフィックシステム(株) | C29: GA801 | D29: EDI
A30: 支払明細書：カシオテクノ(株) ■【注文書】コード：EH905 | B30: カシオテクノ(株) | C30: EH905 | D30: 注文書 | E30: 削除フラグ | G30: 請求書で数件コードあり（銀行口座不一致）
A31: 支払明細書：IDEC AUTO-ID SOLUTIONS(株) ■【注文書】コード：ED709 | B31: IDEC AUTO-ID SOLUTIONS株式会社 | C31: ED709 | D31: 注文書
A32: 支払明細書：(株)寺岡精工 ■【注文書】コード：FA619 | B32: 株式会社寺岡精工 | C32: FA619 | D32: 注文書
A33: 支払明細書：(株)富士通ｾﾞﾈﾗﾙ情報ｼｽﾃﾑ ■【注文書】コード：GG518 | B33: (株)富士通ｾﾞﾈﾗﾙ情報ｼｽﾃﾑ | C33: A191C | D33: 請求書
A34: 支払明細書：ＮＤＩソリューションズ(株)≪≪中締め≫≫ ◆【請求書】コード：C1788 G/L勘定：66150040 | B34: ＮＤＩソリューションズ(株) | C34: C1788 | D34: 請求書
A35: 支払明細書：(株)シーネット≪≪中締め≫≫ ◆【請求書】コード：W0307 G/L勘定：66150040 | B35: (株)シーネット | C35: W0307 | D35: 請求書
A36: 支払明細書：兼松エレクトロニクス(株)≪≪中締め≫≫ ◆【請求書】コード：A868F G/L勘定：66150040 | B36: 兼松エレクトロニクス株式会社 | C36: A868F | D36: 請求書 | F36: EH013 | G36: 納品書
A37: 支払明細書：(株)ジェイ エスキューブ≪≪末締め≫≫ ◆【請求書】コード：P1013 G/L勘定：66150040 | B37: 株式会社ジェイ エスキューブ | C37: P1013 | D37: 請求書
A38: 支払明細書：エプソン販売(株)≪≪末締め≫≫ ◆【請求書】コード：B2328 G/L勘定：66150040 | B38: エプソン販売(株) | C38: B2328 | D38: 請求書
A39: 支払明細書：ミツイワ(株)≪≪末締め≫≫ ◆【請求書】コード：B2555 G/L勘定：66150040 | B39: ミツイワ(株) | C39: B2555 | D39: 請求書
A40: 支払明細書：日本ビジネスコンピュータ(株)≪≪末締め≫≫ ◆【請求書】コード：L1435 G/L勘定：66150040 | B40: 日本ビジネスコンピュータ(株) | C40: L1435 | D40: 請求書 | E40: ＪＢＣＣ株式会社
A41: 支払明細書：富士電機(株)≪≪末締め≫≫ ◆【請求書】コード：A042C G/L勘定：66150040 | B41: 富士電機(株) | C41: A042C | D41: 請求書
A42: 支払明細書：ロジスティードソリューションズ(株)≪≪末締め≫≫ ◆【請求書】コード：A465A G/L勘定：66150040 | B42: ロジスティードソリューションズ株式会社 | C42: A465A | D42: 請求書 | F42: ←2023.4月～ ロジスティードソリューション（株）に社名変更 | K42: 旧：日立物流ソフトウェア(株)
...
