Workbook

Sheet 結合テスト目次
A1: MCM契・解約機能 結合テスト仕様書
A2: 対象：1005/1006/1009/1010/1011/2006/2007/3002/3003/3004/3005/3007/3008、連携経路3001U。作成日：2026/10/05。機能照合反映：2026/10/06。 重複整理：2026/10/08。
A3: 管理214項目、結合実施208件、重複除外6件。単体13画面596件の対応表を更新。単体のOK・帳票への分担・未実施を区別し、旧項番を保持。結合の実行結果は未記入。
A4: 実行順：課題確定→データ準備→単体の前提ケース→INT01～08→INT09。対象外6件は指定工程で確認し、必要な合格証跡を参照。未実施を確認済みとして省略しない。
A6: シート | B6: 対象の業務フロー | C6: テスト件数 | D6: 対象外 | E6: 実テスト件数 | F6: OK | G6: NG | H6: 保留・未実施 | I6: 実施率 | J6: 合格率
A7: INT01_取引先契約 | B7: 取引先契約内容・機器設定 | C7: =INT01_取引先契約!B6 -> 32 | D7: =INT01_取引先契約!D6 -> 0 | E7: =INT01_取引先契約!F6 -> 32 | F7: =INT01_取引先契約!H6 -> 8 | G7: =INT01_取引先契約!J6 -> 0 | H7: =INT01_取引先契約!L6 -> 24 | I7: =INT01_取引先契約!N6 -> 0.25 | J7: =INT01_取引先契約!P6 -> 0.25
A8: INT02_審査承認 | B8: 取引先契約の申請・審査・承認 | C8: =INT02_審査承認!B6 -> 29 | D8: =INT02_審査承認!D6 -> 10 | E8: =INT02_審査承認!F6 -> 19 | F8: =INT02_審査承認!H6 -> 0 | G8: =INT02_審査承認!J6 -> 0 | H8: =INT02_審査承認!L6 -> 19 | I8: =INT02_審査承認!N6 -> 0 | J8: =INT02_審査承認!P6 -> 0
A9: INT03_パック店舗直 | B9: パック契約・店舗直契約 | C9: =INT03_パック店舗直!B6 -> 19 | D9: =INT03_パック店舗直!D6 -> 0 | E9: =INT03_パック店舗直!F6 -> 19 | F9: =INT03_パック店舗直!H6 -> 0 | G9: =INT03_パック店舗直!J6 -> 0 | H9: =INT03_パック店舗直!L6 -> 19 | I9: =INT03_パック店舗直!N6 -> 0 | J9: =INT03_パック店舗直!P6 -> 0
A10: INT04_ユーザー契約 | B10: ユーザー契約内容・変更 | C10: =INT04_ユーザー契約!B6 -> 25 | D10: =INT04_ユーザー契約!D6 -> 8 | E10: =INT04_ユーザー契約!F6 -> 17 | F10: =INT04_ユーザー契約!H6 -> 0 | G10: =INT04_ユーザー契約!J6 -> 0 | H10: =INT04_ユーザー契約!L6 -> 17 | I10: =INT04_ユーザー契約!N6 -> 0 | J10: =INT04_ユーザー契約!P6 -> 0
A11: INT05_製番契約解約 | B11: 契約・解約製番検索／製番確認 | C11: =INT05_製番契約解約!B6 -> 19 | D11: =INT05_製番契約解約!D6 -> 0 | E11: =INT05_製番契約解約!F6 -> 19 | F11: =INT05_製番契約解約!H6 -> 0 | G11: =INT05_製番契約解約!J6 -> 0 | H11: =INT05_製番契約解約!L6 -> 19 | I11: =INT05_製番契約解約!N6 -> 0 | J11: =INT05_製番契約解約!P6 -> 0
A12: INT06_支払い連携 | B12: 支払い明細出力との連携 | C12: =INT06_支払い連携!B6 -> 12 | D12: =INT06_支払い連携!D6 -> 0 | E12: =INT06_支払い連携!F6 -> 12 | F12: =INT06_支払い連携!H6 -> 0 | G12: =INT06_支払い連携!J6 -> 0 | H12: =INT06_支払い連携!L6 -> 12 | I12: =INT06_支払い連携!N6 -> 0 | J12: =INT06_支払い連携!P6 -> 0
A13: INT07_保守点検連携 | B13: 保守点検・帳票との連携 | C13: =INT07_保守点検連携!B6 -> 15 | D13: =INT07_保守点検連携!D6 -> 4 | E13: =INT07_保守点検連携!F6 -> 11 | F13: =INT07_保守点検連携!H6 -> 0 | G13: =INT07_保守点検連携!J6 -> 0 | H13: =INT07_保守点検連携!L6 -> 11 | I13: =INT07_保守点検連携!N6 -> 0 | J13: =INT07_保守点検連携!P6 -> 0
A14: INT08_作業予定連携 | B14: 作業予定一覧・登録・帳票 | C14: =INT08_作業予定連携!B6 -> 32 | D14: =INT08_作業予定連携!D6 -> 1 | E14: =INT08_作業予定連携!F6 -> 31 | F14: =INT08_作業予定連携!H6 -> 0 | G14: =INT08_作業予定連携!J6 -> 0 | H14: =INT08_作業予定連携!L6 -> 31 | I14: =INT08_作業予定連携!N6 -> 0 | J14: =INT08_作業予定連携!P6 -> 0
A15: INT09_共通連携 | B15: 権限・排他・セッション・保存先 | C15: =INT09_共通連携!B6 -> 31 | D15: =INT09_共通連携!D6 -> 1 | E15: =INT09_共通連携!F6 -> 30 | F15: =INT09_共通連携!H6 -> 0 | G15: =INT09_共通連携!J6 -> 0 | H15: =INT09_共通連携!L6 -> 30 | I15: =INT09_共通連携!N6 -> 0 | J15: =INT09_共通連携!P6 -> 0
A17: 合計（率は総件数から再計算） | C17: =SUM(C7:C15) -> 214 | D17: =SUM(D7:D15) -> 24 | E17: =SUM(E7:E15) -> 190 | F17: =SUM(F7:F15) -> 8 | G17: =SUM(G7:G15) -> 0 | H17: =SUM(H7:H15) -> 182 | I17: =IF(E17=0,0,(F17+G17)/E17) -> 0.042105263 | J17: =IF(E17=0,0,F17/E17) -> 0.042105263
A20: 重複確認 | C20: 単体596件を対応表に1回ずつ記録。単体に委ねる349件、結合で追加確認206件、帳票等へ分担41件。実績の転記なし。
A21: 単体収録状況 | C21: 旧記載の未収録7画面は収録済み。単体13画面596件を「単体との対応」で管理。収録済み＝合格ではない。2007-10の期待訂正・再判定、前提ケースと帳票分担先の証跡確認はQ10で継続管理。
A22: 実施結果 | C22: 黄色のI～Oに実績を入力。最終判定Pは再テスト結果Mを優先し、Mが空なら初回I、両方空なら未実施。再テストのみ入力する場合も、以前の結果・不具合・再実施理由をLまたはQに記録する。
A23: 判定と証跡 | C23: 対象ID・期間ID・出力ファイル・変更前後DBの証跡を不具合内容または備考へ記録。見た目だけで連携成功としない。
A24: 未確認 | C24: 添付実体、Officeのアプリ起動・印刷、SMTPと応答性能はこの仕様書作成では実行確認していない。

Sheet 対象・観点一覧
A1: 対象14画面と確認工程の対応
A2: 今回の受領単体13画面596件と結合208件で分担を管理。件数や対応先の存在だけで全条件網羅・実行合格とは判定しない。
A3: 1006U・2007Uは2画面、3004Uは全9タブを含む。3001UはTK審査・承認／書類NO連携経路として追加し、実機での結果判定は未実施。
A5: 機能ID | B5: 画面名 | C5: 共有単体版の収録 | D5: 結合ケースID | E5: 結合の実施区分 | F5: 単体に委ねる範囲 | G5: 課題ID
A6: MCM1005U | B6: 取引先契約内容 | C6: 収録 30件 | D6: INT01-01, INT01-02, INT01-03, INT01-04, INT01-05, INT01-06, INT01-07, INT01-08, INT01-09, INT01-10, INT01-11, INT01-12, INT01-13, INT01-14, INT01-15, INT01-16, INT01-17, INT01-18, INT02-01, INT02-02, INT02-03, INT02-04, INT02-05, INT02-06, INT02-07, INT02-08, INT02-09, INT02-10, INT02-12, INT02-13, INT02-14, INT02-15, INT02-21, INT03-02, INT03-03, INT03-07, INT03-10, INT03-11, INT03-15, INT05-04, INT05-05, INT05-06, INT05-09, INT06-01, INT06-02, INT06-03, INT06-04, INT06-05, INT06-08, INT06-09, INT06-10, INT06-11, INT07-01, INT07-02, INT07-03, INT07-04, INT07-05, INT07-06, INT07-07, INT07-08, INT07-09, INT08-02, INT08-03, INT08-04, INT08-05, INT08-08, INT08-09, INT08-10, INT08-14, INT08-22, INT09-01, INT09-04, INT09-05, INT09-08, INT09-09, INT09-12, INT09-14, INT09-17, INT09-18, INT09-19, INT09-20, INT09-21, INT09-22, INT09-23, INT09-24, INT09-25, INT09-26, INT01-19, INT02-22, INT02-23, INT09-28, INT01-20, INT01-21, INT01-22, INT01-23, INT01-24, INT01-25, INT01-26, INT01-27, INT02-24, INT03-17, INT03-18, INT06-12, INT06-13, INT07-14, INT07-15, INT08-23, INT08-24, INT08-25, INT08-26, INT08-27, INT08-28, INT08-29, INT08-30, INT08-31, INT08-33, INT03-19, INT01-28, INT01-29, INT01-30, INT02-25, INT09-30, INT09-31, INT01-31, INT01-32, INT02-26, INT02-27, INT02-28, INT02-29 | E6: 正常系 / 仕様照合 / 異常系 / 排他 / 権限連携 / セッション / 環境連携 / 取消 / 更新連携 | F6: 共有版の単体に収録。表示・入力・単独操作は単体へ分担し、結合はDB・画面間・後続処理への追加判定のみ実施。対象外6件は対応表の指定先へ分担。 | G6: Q02 / Q04 / Q08
A7: MCM1006U | B7: 取引先契約機器設定（2画面） | C7: 収録 27件 | D7: INT01-02, INT01-03, INT01-04, INT01-05, INT01-06, INT01-07, INT01-08, INT01-09, INT01-10, INT01-11, INT01-12, INT01-18, INT03-02, INT03-10, INT05-09, INT09-04, INT09-05, INT09-06, INT09-17, INT09-18, INT09-19, INT01-19, INT09-28, INT01-20, INT01-21, INT01-22, INT01-28, INT01-29 | E7: 正常系 / 仕様照合 / 権限連携 / 排他 / セッション | F7: 共有版の単体に収録。表示・入力・単独操作は単体へ分担し、結合はDB・画面間・後続処理への追加判定のみ実施。対象外6件は対応表の指定先へ分担。 | G7: Q01
A8: MCM1009U | B8: パック契約・解約 | C8: 収録 20件 | D8: INT03-01, INT03-02, INT03-03, INT03-04, INT03-05, INT03-06, INT03-07, INT03-08, INT05-11, INT09-04, INT09-07, INT03-17, INT03-19 | E8: 正常系 / 異常系 / 排他 / 権限連携 / 取消 | F8: 共有版の単体に収録。表示・入力・単独操作は単体へ分担し、結合はDB・画面間・後続処理への追加判定のみ実施。対象外6件は対応表の指定先へ分担。 | G8: Q07
A9: MCM1010U | B9: 店舗直契約・解約 | C9: 収録 21件 | D9: INT03-09, INT03-10, INT03-11, INT03-12, INT03-13, INT03-14, INT03-15, INT03-16, INT09-05, INT09-07, INT03-18, INT03-19 | E9: 正常系 / 異常系 / 排他 / 権限連携 / 取消 | F9: 共有版の単体に収録。表示・入力・単独操作は単体へ分担し、結合はDB・画面間・後続処理への追加判定のみ実施。対象外6件は対応表の指定先へ分担。 | G9: －
A10: MCM1011U | B10: 審査・承認（取引先契約） | C10: 収録 26件 | D10: INT02-01, INT02-02, INT02-03, INT02-04, INT02-05, INT02-06, INT02-07, INT02-08, INT02-09, INT02-10, INT02-11, INT02-12, INT02-13, INT02-14, INT02-15, INT02-16, INT02-17, INT02-18, INT02-19, INT02-20, INT02-21, INT06-08, INT09-03, INT09-07, INT09-08, INT09-23, INT09-25, INT09-26, INT02-22, INT02-23, INT02-24, INT01-30, INT02-25 | E10: 正常系 / 異常系 / 排他 / 外部連携 / 権限連携 / 環境連携 / 仕様照合 | F10: 共有版の単体に収録。表示・入力・単独操作は単体へ分担し、結合はDB・画面間・後続処理への追加判定のみ実施。対象外6件は対応表の指定先へ分担。 | G10: Q02 / Q03 / Q08 / Q15
A11: MCM2006U | B11: ユーザー契約内容 | C11: 収録 26件 | D11: INT04-01, INT04-02, INT04-03, INT04-04, INT04-05, INT04-06, INT04-07, INT04-08, INT04-09, INT04-10, INT04-11, INT04-12, INT04-13, INT04-14, INT04-15, INT04-16, INT05-03, INT05-05, INT05-06, INT05-07, INT05-13, INT05-14, INT05-15, INT05-17, INT06-07, INT08-01, INT08-05, INT08-06, INT08-08, INT08-14, INT08-22, INT09-02, INT09-13, INT09-15, INT09-17, INT09-18, INT09-19, INT09-20, INT09-21, INT04-17, INT09-28, INT09-29, INT04-18, INT04-19, INT04-21, INT04-22, INT05-18, INT06-13, INT08-23, INT08-24, INT08-25, INT08-26, INT08-27, INT08-28, INT08-29, INT08-30, INT08-31, INT08-32, INT04-23, INT04-24, INT04-25, INT05-19, INT09-31 | E11: 正常系 / 仕様照合 / 異常系 / 排他 / 権限連携 / セッション | F11: 共有版の単体に収録。表示・入力・単独操作は単体へ分担し、結合はDB・画面間・後続処理への追加判定のみ実施。対象外6件は対応表の指定先へ分担。 | G11: Q04 / Q05 / Q08 / Q12 / Q13 / Q14、Q17
A12: MCM2007U | B12: ユーザー契約内容変更（2画面） | C12: 収録 23件 | D12: INT04-02, INT04-03, INT04-04, INT04-05, INT04-06, INT04-07, INT04-08, INT04-09, INT04-16, INT05-07, INT09-06, INT09-17, INT09-18, INT09-19, INT09-28, INT04-18, INT04-19, INT04-23, INT04-24, INT04-25 | E12: 正常系 / 仕様照合 / 権限連携 / 排他 / セッション | F12: 共有版の単体に収録。表示・入力・単独操作は単体へ分担し、結合はDB・画面間・後続処理への追加判定のみ実施。対象外6件は対応表の指定先へ分担。 | G12: Q01 / Q10 / Q13
A13: MCM3002U | B13: 支払い明細出力指示 | C13: 収録 35件 | D13: INT01-08, INT01-15, INT01-16, INT02-05, INT03-05, INT03-13, INT04-13, INT05-11, INT05-13, INT05-14, INT05-16, INT06-01, INT06-02, INT06-03, INT06-04, INT06-05, INT06-07, INT06-08, INT06-09, INT06-10, INT06-11, INT07-01, INT07-11, INT07-12, INT07-13, INT04-17, INT04-21, INT05-18, INT06-12, INT06-13, INT07-14, INT07-15 | E13: 正常系 / 異常系 | F13: 共有版の単体に収録。表示・入力・単独操作は単体へ分担し、結合はDB・画面間・後続処理への追加判定のみ実施。対象外6件は対応表の指定先へ分担。 | G13: Q04 / Q10 / Q11 / Q16
A14: MCM3003U | B14: 保守点検 | C14: 収録 61件 | D14: INT01-16, INT02-05, INT07-01, INT07-02, INT07-03, INT07-04, INT07-05, INT07-06, INT07-07, INT07-08, INT07-09, INT07-10, INT07-11, INT07-12, INT07-13, INT07-14, INT07-15, INT01-29 | E14: 正常系 / 更新連携 | F14: 共有版の単体に収録。表示・入力・単独操作は単体へ分担し、結合はDB・画面間・後続処理への追加判定のみ実施。対象外6件は対応表の指定先へ分担。 | G14: Q04 / Q10 / Q16
A15: MCM3004U | B15: 作業予定一覧（9タブ） | C15: 収録 147件 | D15: INT04-04, INT04-10, INT04-15, INT08-01, INT08-02, INT08-03, INT08-04, INT08-05, INT08-06, INT08-07, INT08-08, INT08-09, INT08-10, INT08-12, INT08-13, INT08-14, INT08-16, INT08-17, INT08-18, INT08-19, INT08-20, INT08-21, INT08-22, INT09-10, INT09-11, INT09-27, INT01-23, INT01-24, INT01-25, INT04-22, INT08-23, INT08-24, INT08-25, INT08-26, INT08-27, INT08-28, INT08-29, INT08-30, INT08-31, INT08-32, INT08-33, INT08-34 | E15: 正常系 / 異常系 / 権限連携 / 性能連携 | F15: 共有版の単体に収録。表示・入力・単独操作は単体へ分担し、結合はDB・画面間・後続処理への追加判定のみ実施。対象外6件は対応表の指定先へ分担。 | G15: Q09 / Q10 / Q16
A16: MCM3005U | B16: 作業予定登録 | C16: 収録 65件 | D16: INT06-01, INT06-02, INT06-04, INT06-05, INT06-09, INT06-10, INT08-07, INT08-16, INT08-17, INT08-18, INT08-19, INT08-20, INT08-21, INT09-11, INT09-16, INT09-20, INT09-21, INT09-22, INT09-23, INT09-24, INT09-25, INT09-26, INT06-12, INT06-13, INT08-23, INT08-24, INT08-25, INT08-26, INT08-27, INT08-28, INT08-29, INT08-30, INT08-34, INT09-30, INT09-31 | E16: 正常系 / 異常系 / 権限連携 / 排他 / セッション / 環境連携 | F16: 共有版の単体に収録。表示・入力・単独操作は単体へ分担し、結合はDB・画面間・後続処理への追加判定のみ実施。対象外6件は対応表の指定先へ分担。 | G16: Q02 / Q08 / Q10
... A19: MCM3001U | B19: TK審査・承認／書類NOリンク | C19: 移行元3001-7/8/12/15を結合へ引継ぎ | D19: INT02-26, INT02-27, INT02-28, INT02-29 | E19: 正常系 / 審査・承認 / 差戻し / 画面遷移 | F19: 3001U経路の連携判定のみ。単体側の判定履歴は変更せず、実施時に確認。 | G19: －

Sheet INT01_取引先契約
A1: MCM契・解約機能 結合テスト仕様書｜取引先契約内容・機器設定
A2: 実施前にE列を確認。登録確認はOK、取消ケースは取消。複数パターンは全て実施・期待一致ならOK、期待不一致ありならNG、NGなしで未実施・判断待ちが残る場合は保留。Q列にパターン別結果・実ID・証跡を追記し、既存の根拠は消さない。
A3: 単体13画面596件の表示・入力・単独判定は「単体との対応」へ分担。対象外は重複除外の設定で実行合格ではない。Q付きの期待・環境を確定してから追加判定を実施。
A4: 最終判定は再テスト結果を優先。「保留」集計は未実施も含む残件。合格率＝OK／実テスト件数。表示形式・ネイティブOfficeの動作は実行時に確認。
A6: テスト件数 | B6: =COUNTA(A10:A41) -> 32 | C6: 対象外件数 | D6: =COUNTIF(P10:P41,"対象外") -> 0 | E6: 実テスト件数 | F6: =B6-D6 -> 32 | G6: 完了件数OK | H6: =COUNTIF(P10:P41,"OK") -> 8 | I6: NG件数 | J6: =COUNTIF(P10:P41,"NG") -> 0 | K6: 保留 | L6: =MAX(0,F6-H6-J6) -> 24 | M6: 実施率 | N6: =IF(F6=0,0,(H6+J6)/F6) -> 0.25 | O6: 合格率 | P6: =IF(F6=0,0,H6/F6) -> 0.25
A8: 単体との重複を除いた結合テストケース
A9: 項番 | B9: 分類 | C9: テスト観点 | D9: 関連画面 | E9: 前提条件（ここを読んで準備する） | F9: 操作手順 | G9: 期待結果 | H9: 期待メッセージ | I9: テスト結果 | J9: 実施者 | K9: 実施日 | L9: 不具合内容 | M9: 再テスト結果 | N9: 再テスト実施者 | O9: 再テスト実施日 | P9: 最終判定 | Q9: 備考／根拠
A10: INT01-01 | B10: 正常系 | C10: 検索行の契約キーと履歴期間の一致 | D10: 1003U→1005U | E10: 【用意するもの】過去・現在・未来など複数の期間を持つ取引先契約1件と、契約NOが似ている別の契約1件。 【準備】1003U（契約を検索する画面）で両方が検索できることを確認。1005U（契約内容の画面）で各期間の日付、取引先、プラント、機器を記録する。 【完了の目安】どちらの契約か、どの期間かを番号と日付で区別できる。 【全ケース共通】試験専用の環境・データを使用。接続先と実行日／月を記録し、画面の識別番号（ID）・変更前情報を控える。DBの確認は担当者に読取だけを依頼し、自分で書き換えない。 | F10: 手順1：1003Uで対象行を開く。 手順2：契約ID・期間IDを記録し、別期間を開いてDBの同じキーと照合する。 | G10: 選択した契約の期間・取引先・プラント・機器が一貫して同じキーを参照し、隣の契約や別期間の内容が混入しない。 | H10: －（表示文言のみの確認は単体に委ねる） | I10: OK | J10: 池澤 | K10: 46309 | P10: =IF(M10<>"",M10,IF(I10<>"",I10,"未実施")) -> OK | Q10: 関連単体：1005-1 単体の表示・単独操作ではなく、期待結果の連携部分を追加判定。 根拠：R1005
A11: INT01-02 | B11: 正常系 | C11: 見積から新規契約を作成し検索へ反映 | D11: 1003U→1006U1/U2→1005U→1003U | E11: 【用意するもの】まだ契約を作っていない、破棄されていない取引先見積1件。担当者Aには取引先契約の作成権限が必要。 【準備】1003Uで対象見積が検索できることを確認。見積NO、取引先、納入先、プラント、期間、機器と単価を記録し、契約に入れる機器／入れない機器を決める。 【完了の目安】元見積の情報と採用予定機器がわかり、契約が未作成である。「契約作成」は本テストで押す。 【全ケース共通】試験専用の環境・データを使用。接続先と実行日／月を記録し、画面の識別番号（ID）・変更前情報を控える。DBの確認は担当者に読取だけを依頼し、自分で書き換えない。 | F11: 手順1：1003Uの対象見積行で「契約作成」を押し、直後に1006Uの初期表示と引継ぎ項目を対象行と照合する。 手順2：構成・明細・個体を選び摘要し、1005Uで登録する。 手順3：1003Uを同条件で再検索し契約を開く。 | G11: 選定した見積IDに対応する契約が検索に現れる。契約・期間・選定機器・単価の親子キーが一致し、選定しなかった機器は契約に入らない。 登録採番後は仮の負IDを残さず、期間・構成・明細・個体・単価の外部キーを同じ親へ結び直す。 遷移直後に1005Uへ移り、取引先見積契約時間ID、取引先ID・コード・名、納入先コード・名、サポートID、プラント名・IDが1003Uの対象行と一致する。 | H11: －（表示文言のみの確認は単体に委ねる） | I11: OK | J11: 池澤 | K11: 46309 | P11: =IF(M11<>"",M11,IF(I11<>"",I11,"未実施")) -> OK | Q11: 関連単体：1005-17, 1006-1, 1006-2, 1006-24 単体の表示・単独操作ではなく、期待結果の連携部分を追加判定。 根拠：R1006 / R1005 移行元：1003-24 遷移先に関する移行元の疑義は確定不具合ではなく、実施時の確認事項。
A12: INT01-03 | B12: 正常系 | C12: 複数見積の選定と契約への集約 | D12: 1006U1/U2→1005U | E12: 【用意するもの】同じプラントに属し、見積NOと単価が異なる未契約見積2件。同じ機器明細に、保守条件の異なる単価が複数あるもの。 【準備】見積ごとに機器、個体（機器1台ごとの管理データ）、数量、単価、標準価格、仕切価格、保守条件を記録する。旧システム（VB）の担当者に単価の並び順と先頭の単価を確認してもらう。 【完了の目安】各機器・金額がどちらの見積に由来するか、保守条件をどの単価から採るかを照合できる。 【全ケース共通】試験専用の環境・データを使用。接続先と実行日／月を記録し、画面の識別番号（ID）・変更前情報を控える。DBの確認は担当者に読取だけを依頼し、自分で書き換えない。 | F12: 手順1：2見積を選択して次へ。 手順2：各見積の対象個体を摘要、登録後に契約機器・単価を元見積と照合する。 手順3： 明細金額・標準価格・仕切価格を単価別の保存値から照合し、保守表示の採用元も確認する。 | G12: 選択した見積に由来する機器・単価だけが契約へ渡り、見積NO・機器明細ID・個体IDの対応が崩れない。金額・数量の異なる行が取り違えられない。 明細金額は対象単価の合算と数量に一致し、保守条件はVBの並び順で先頭の単価から採用する。別単価の条件を無条件に合算しない。 | H12: －（表示文言のみの確認は単体に委ねる） | I12: 保留 | J12: 池澤 | K12: 46309 | L12: DB画面確認が残っている | P12: =IF(M12<>"",M12,IF(I12<>"",I12,"未実施")) -> 保留 | Q12: 関連単体：1006-12, 1006-13, 1006-24 単体の表示・単独操作ではなく、期待結果の連携部分を追加判定。 根拠：R1006 / R1005
A13: INT01-04 | B13: 正常系 | C13: 下位個体の除外が保存数量と帳票に反映 | D13: 1006U2→1005U→1003P | E13: 【用意するもの】同じ機器明細に、数量の異なる個体が2件以上ある未契約見積。 【準備】個体ごとの管理番号と数量を記録し、契約に入れる個体と除外する個体を決める。採用する個体の数量を足した値も記録する。 【完了の目安】採用／除外が番号で区別でき、登録後の数量・金額・帳票を照合できる。個体の選定・登録・発行は本テストで行う。 【全ケース共通】試験専用の環境・データを使用。接続先と実行日／月を記録し、画面の識別番号（ID）・変更前情報を控える。DBの確認は担当者に読取だけを依頼し、自分で書き換えない。 | F13: 手順1：個体の一部だけ契約有無をONにして摘要、登録・契約発行。 手順2：契約明細・単価数量・帳票を選定個体合計と照合する。 | G13: 契約明細と単価の数量が採用個体の数量合計と一致し、除外個体が帳票の数量・金額に加算されない。 | H13: －（表示文言のみの確認は単体に委ねる） | I13: OK | J13: 池澤 | K13: 46309 | P13: =IF(M13<>"",M13,IF(I13<>"",I13,"未実施")) -> OK | Q13: 関連単体：1006-18, 1006-19, 1006-20, 1006-21, 1006-24 単体の表示・単独操作ではなく、期待結果の連携部分を追加判定。 根拠：R1006 / R1005
A14: INT01-05 | B14: 正常系 | C14: 未選定見積の構成が契約に混入しない | D14: 1006U1/U2→1005U | E14: 【用意するもの】同名の機器を持つ未契約見積2件。片方だけを契約作成に使う。 【準備】採用する見積と採用しない見積の見積NO、機器・明細・個体・単価の管理番号を記録する。 【完了の目安】機器名が同じでも所属見積を番号で区別できる。採用しない見積の機器が保存されないか確認できる。 【全ケース共通】試験専用の環境・データを使用。接続先と実行日／月を記録し、画面の識別番号（ID）・変更前情報を控える。DBの確認は担当者に読取だけを依頼し、自分で書き換えない。 | F14: 手順1：見積を1件だけ選び、2画面目で対象構成を摘要して登録する。 手順2：契約の個体ID一覧と選択元を照合する。 | G14: 画面に見えていても前画面の未選定見積に属する構成・明細・個体・単価は保存されない。 | H14: －（表示文言のみの確認は単体に委ねる） | I14: OK | J14: 池澤 | K14: 46309 | P14: =IF(M14<>"",M14,IF(I14<>"",I14,"未実施")) -> OK | Q14: 関連単体：1006-14, 1006-15, 1006-16, 1006-17 単体の表示・単独操作ではなく、期待結果の連携部分を追加判定。 根拠：R1006 / R1005
A15: INT01-06 | B15: 正常系 | C15: 期間を短縮した選定単価の受け渡し | D15: 1006U1/U2→1005U→1003P | E15: 【用意するもの】未契約見積、出精値引き0、数量2。「入力値・期待値表」の5期間条件それぞれに、標準／仕切が割り切れる単価Aと余りを持つ単価Bを別契約で用意する。計10パターン。 ③④の対象単価と補助単価は、同一の元見積契約時間IDに属する別期間へ登録する。見積情報の行を期間数だけ複製して選ぶ方法は使わない。契約全期間を覆う補助期間を用意し、同じ機器明細＋個体の組は元見積の個体明細に1回だけ登録する。 登録する新規契約NOは、管理者が試験専用の未使用番号を準備表へ記入する。DBの契約ID採番と画面の契約NOは別。契約NOが自動設定されると仮定しない。 【入力値】「入力値・期待値表」の期間・金額。A／Bは実在データと主張する値ではなく、作成する試験データの設計値。実施日が進んだ場合は全関連年を同じ年数だけ移し、月数・期待額を維持する。 入力値・期待値表（元単価A：標準12,000／仕切9,600、B：標準12,005／仕切9,607、数量2） 条件｜対象元期間｜契約期間｜補助期間・単価｜Aの標準／仕切合計｜Bの標準／仕切合計 ①開始側短縮｜2027/04/01～2028/03/31｜2027/07/01～2028/03/31｜なし｜18,000／14,400｜18,000／14,400 ②終了側短縮｜2027/04/01～2028/03/31｜2027/04/01～2027/12/31｜なし｜18,000／14,400｜18,010／14,414 ③対象元期間が内側｜2027/07/01～2027/12/31｜2027/04/01～2028/03/31｜4～6月と翌1～3月に各標準3,000／仕切2,400｜36,000／28,800｜36,010／28,814 ④対象元期間が外側｜2027/01/01～2027/03/31｜2027/04/01～2027/12/31｜契約全期間に標準9,000／仕切7,200｜18,000／14,400｜18,000／14,400 ⑤元終了なし｜2027/04/01～空欄｜2027/07/01～2028/03/31｜なし｜18,000／14,400｜18,010／14,414 採用対象単価1件の期待値（金額の順は標準／仕切）：①A/Bとも9,000／7,200、②A9,000／7,200・B9,005／7,207、③A12,000／9,600・B12,005／9,607に補助2件各3,000／2,400を加算、④対象元単価0件で補助9,000／7,200のみ、⑤A9,000／7,200・B9,005／7,207。 【全ケース共通】試験専用の環境・データを使用。接続先と実行日／月を記録し、画面の識別番号（ID）・変更前情報を控える。DBの確認は担当者に読取だけを依頼し、自分で書き換えない。 | F15: 手順1：メニューの「取引先見積・契約検索」を押してMCM1003Uを開く。「見積依頼NO」にデータ準備表の各パターンの見積のNOを入力し、「検索」を押す。状態・承認状態のチェックは各パターンの見積の状態を含める。 手順2：検索結果で各パターンの見積の「依頼NO」「取引先名」「サポートID」「プラント名」を照合し、右端の2つの「契約」列のうち左側にあるリンクを押す。MCM1006U①が開く。右側の破棄リンクは押さない。 手順3：1006U①「期間」に「入力値・期待値表」の契約開始・終了日を入力し、「≪見積情報≫」でそのパターンの見積だけをONにして「次へ」を押す。 手順4：MCM1006U②の左上「≪機器構成パターン≫」、右上「≪納入機器明細≫」、下段「≪機器個体・明細≫」で、そのパターンの対象明細・個体数量2を選定する。選定する行のチェックをONにし、除外する行をOFFにする。品名・型式・個体名・シリアル番号と「見積依頼NO」を準備表と照合して選ぶ。行を選択すると表示する下位行が切り替わるため、別の構成・明細の行も選択してチェック状態を確認する。 手順5：「摘要」を押し、1005U機器情報の標準価格・仕切価格・数量・標準計・仕切計と、期間右側の「≪標準価格≫」の「合計」と、出精値引きの下の「合計」を記録する。 手順6：MCM1005U上段「契約NO」と期間内「契約NO」に準備した未使用の試験契約NOを入力する。「≪支払情報≫」で準備表の回数・月を設定する。開始月はON、回数はON月数以上。指定がない場合は回数1・開始月だけONにする。MCM1005Uで「登録」を押す。新規登録時の個体期限設定確認が表示された場合は「OK」、続く「登録を実施します。よろしいですか？」は「OK」を押す。「登録が完了しました。」の通知を確認する。 手順7：選択期間を変えずに「契約発行」を押す。未保存の場合は登録確認の「OK」を押す。取得した「契約手続依頼書.xls」を開いて、Excelの表示・印刷レイアウトだけでなく、下記の転記内容を確認する。 手順8：DB担当者に採用元単価ID、切り詰め後の単価開始・終了日、標準・仕切保存値、契約明細数量を確認してもらう。 手順9：取得した帳票の「見積金額（仕切）」と準備表の数量倍の合計を比較する。次のパターンは別の未契約見積から開始し、登録済み契約を使い回さない。 | G15: ・単価A／Bの採用値と画面集計は「入力値・期待値表」に一致する。④の期間外単価は採用されない。⑤は元終了日なしのため元月数12で、開始側を短くしても余りを加える。 ・帳票「見積金額（仕切）」は「入力値・期待値表」の仕切合計に一致する。帳票に元単価1件ごとの標準価格・日付が載るとは期待しない。 ・MCM_TK_TANKAの採用元単価ID・期間・HYOJUN_KIN・SIKIRI_KINが「入力値・期待値表」の採用値と一致する。SURYO_NMはMCM_TK_KIKIMEISAIで2。期間合計は採用単価合計×数量、出精値引き0。元見積の単価・期間は変わらない。 | H15: －（表示文言のみの確認は単体に委ねる） | I15: OK | J15: 池澤 | K15: 46311 | P15: =IF(M15<>"",M15,IF(I15<>"",I15,"未実施")) -> OK | Q15: 関連単体：1006-9, 1006-11, 1006-24 単体の表示・単独操作ではなく、期待結果の連携部分を追加判定。 根拠：R1006/R1005 setTankaKin・GetYYYYMM、VB1006-08/VB1005-25 VB setTankaKin／GetYYYYMMの月割り・余りと終了日なし例外を反映。単価保存値、数量倍集計、帳票仕切合計を別判定。 ④の対象元期間は1006U①の期間抽出で対象外となる。対象外元単価を②に表示させて除外する操作ではなく、契約へ入らないことを確認する。 元Excel行：15。実施区分：通常＋DB担当者の読取確認。元の画面間フロー：1006U1/U2→1005U→1003P。
A16: INT01-07 | B16: 正常系 | C16: 未承認の未来期間を同日開始で変更 | D16: 1005U→1006U→1005U | E16: 【用意するもの】開始日がテスト実施日より後の最新期間を持つ取引先契約。対象期間に承認済み添付がなく、出精値引きが0のもの。 【準備】1005Uで開始日、添付の状態、期間の管理番号、機器、前の有効期間を記録する。変更予定日は元の開始日と同じ日にする。 【完了の目安】未来・未承認の条件が確認でき、変更前の期間と機器が特定できる。機器変更はまだ行わない。 【全ケース共通】試験専用の環境・データを使用。接続先と実行日／月を記録し、画面の識別番号（ID）・変更前情報を控える。DBの確認は担当者に読取だけを依頼し、自分で書き換えない。 | F16: 手順1：変更摘要開始日を元開始日と同じにし、機器を入れ替えて摘要・登録。 手順2：履歴と期間IDを再確認する。 | G16: 未承認の未来期間を更新し、置換だけのために期間を増やさない。前の有効期間の日付調整と、更新対象の機器・金額が保存される。現在・過去・承認済み未来期間の履歴分岐はINT01-20/21で別判定する。 | H16: －（表示文言のみの確認は単体に委ねる） | I16: OK | J16: 池澤 | K16: 46309 | P16: =IF(M16<>"",M16,IF(I16<>"",I16,"未実施")) -> OK | Q16: 関連単体：1006-3, 1006-25 単体の表示・単独操作ではなく、期待結果の連携部分を追加判定。 根拠：R1005 Screen 100～281 / TabControl 1630～1700、R1006
A17: INT01-08 | B17: 正常系 | C17: 期間途中からの変更で履歴を分割 | D17: 1005U→1006U→1005U→3002U | E17: 【用意するもの】最新の現在期間（開始≦実施日≦終了）を持つ契約A。審査中・承認中・解約・破棄でなく、変更が活性。出精値引き0。 【準備】変更日Xは期間途中の月初日。旧機器Aと新Bの単価・数量、旧期間の支払回数・ON月、変更前後の支払月と期待額を記録。Q11／Q16に従いユーザー契約・確認済み製番・支払ビューが抽出できる状態をDB担当者が用意する。 【入力値】例：実施日2026/10/14、旧2026/04/01～2027/03/31、X=2026/11/01。比較月2026/10・2026/11。実施日が違う場合は現在期間となる日付を準備表で確定する。 【全ケース共通】試験専用の環境・データを使用。接続先と実行日／月を記録し、画面の識別番号（ID）・変更前情報を控える。DBの確認は担当者に読取だけを依頼し、自分で書き換えない。 | F17: 手順1：メニューの「取引先見積・契約検索」を押してMCM1003Uを開く。「契約NO」にデータ準備表の契約Aの契約NOを入力し、「検索」を押す。状態・承認状態のチェックは契約Aの状態を含める。 手順2：検索結果の「契約NO」「取引先名」「サポートID」「プラント名」が契約Aと一致する行の「契約NO」リンクを押す。MCM1005U「取引先契約内容」が開く。 手順3：現在期間の開始日のタブを選び、「変更摘要開始日」にXを入力して「変更」を押す。 手順4：1006U①「期間」の開始日Xを確認し、終了日に旧期間の終了日を入力する。新Bの見積だけをON、不要な旧見積をOFFにして「次へ」。例なら2026/11/01～2027/03/31。自動設定の2027/10/31のまま進めない。 手順5：MCM1006U②の左上「≪機器構成パターン≫」、右上「≪納入機器明細≫」、下段「≪機器個体・明細≫」で、新機器Bのみを選定する。選定する行のチェックをONにし、除外する行をOFFにする。品名・型式・個体名・シリアル番号と「見積依頼NO」を準備表と照合して選ぶ。行を選択すると表示する下位行が切り替わるため、別の構成・明細の行も選択してチェック状態を確認する。 手順6：「摘要」を押す。1005Uの新期間で「≪支払情報≫」の「回数」と月チェックを準備表の新期間の設定にする。旧期間の設定は変更しない。 手順7：MCM1005Uで「登録」を押し、「登録を実施します。よろしいですか？」の「OK」を押す。「登録が完了しました。」の通知を確認する。 手順8：MCM1005Uの「閉じる」を押してMCM1003Uへ戻り、記録した契約NOで「検索」を押す。「契約NO」リンクを押し、開始日で識別した期間タブを選び直す。 手順9：旧期間→新期間の順にタブを選び、期間・機器・金額・支払回数／月を記録する。 手順10：確認した画面内容を記録し、現在の画面の「閉じる」を押す。戻り先が業務画面の場合はその画面の「閉じる」も押し、メニューまで戻る。離脱確認が出たら、開始前に記録した離脱確定の選択肢を押す。支払い明細出力指示（MCM3002U）をメニューから開く。「支払い月」に準備表の年月（yyyy/MM）を入力し、準備した支払回数に対応する「年払い」又は「月払い」を選んで「出力」を押す。取得したZIPを展開し、中の支払い明細と発注確認書のExcelを開く。各条件の対象契約NO・取引先・対象月で行を識別する。 手順11：変更前月と変更後月の2回出力し、DB担当者に支払ビューの採用期間IDと金額の元行を確認してもらう。 | G17: ・旧期間終了はXの前日、新期間開始はX、旧開始と新終了は準備表どおり。旧期間にA、新期間にBを表示する。旧と新の有効期間の日付に重複・空白がない。 ・変更前月のExcelは旧Aの契約期間・仕切額、変更後月は新Bの契約期間・仕切額に一致する。期中変更で年払い等の条件が異なる場合は準備表の支払条件に対応する出力月で比較する。 ・旧期間IDは維持、新期間IDが1件増える。旧終了=X−1日、新開始=X。旧Aの履歴価格は変更前のまま、新Bの元単価IDと価格は準備表に一致。支払親子・ビューの対象期間が前後月で準備した旧新IDに一致する。 | H17: －（表示文言のみの確認は単体に委ねる） | P17: =IF(M17<>"",M17,IF(I17<>"",I17,"未実施")) -> 未実施 | Q17: 関連単体：1006-3, 1006-25 単体の表示・単独操作ではなく、期待結果の連携部分を追加判定。 根拠：R1005 / R1006 / R3002 未承認未来の置換条件は07／28。新期間の支払回数0のまま登録して、支払出力0件を不具合と判定しない。Q11／Q16未解消なら支払出力の部分は保留し、期間分割の判定と分ける。 元Excel行：17。実施区分：通常＋DB担当者の読取確認。元の画面間フロー：1005U→1006U→1005U→3002U。
A18: INT01-09 | B18: 正常系 | C18: 期間末日の翌日から更新期間を追加 | D18: 1005U→1006U→1005U | E18: 【用意するもの】最新が現在又は過去の契約Aを用意する。未来未承認期間は使用しない。変更ボタンが活性、出精値引き0。更新終了Yは実施日以後とし、新期間の支払設定を編集できる条件にする。 【準備】旧期間終了E、更新開始X=Eの翌日、更新終了Y=Xから1年後の前日を記録する。旧期間のID・全期間件数・機器・価格をDB担当者が記録する。X～Yを覆う更新元見積Bと新機器Bを準備する。 【入力値】変更摘要開始日＝旧終了翌日。1006U終了日＝更新開始の1年後の前日。実値を準備表に記入する。 【全ケース共通】試験専用の環境・データを使用。接続先と実行日／月を記録し、画面の識別番号（ID）・変更前情報を控える。DBの確認は担当者に読取だけを依頼し、自分で書き換えない。 | F18: 手順1：メニューの「取引先見積・契約検索」を押してMCM1003Uを開く。「契約NO」にデータ準備表の契約Aの契約NOを入力し、「検索」を押す。状態・承認状態のチェックは契約Aの状態を含める。 手順2：検索結果の「契約NO」「取引先名」「サポートID」「プラント名」が契約Aと一致する行の「契約NO」リンクを押す。MCM1005U「取引先契約内容」が開く。 手順3：旧期間タブの「変更摘要開始日」にXを入力して「変更」を押す。変更日が過去日の場合の確認は「OK」を押す。 手順4：1006U①で開始日Xを確認し、終了日にYを入力する。更新元見積BをONにして「次へ」を押す。 手順5：MCM1006U②の左上「≪機器構成パターン≫」、右上「≪納入機器明細≫」、下段「≪機器個体・明細≫」で、更新機器Bを選定する。選定する行のチェックをONにし、除外する行をOFFにする。品名・型式・個体名・シリアル番号と「見積依頼NO」を準備表と照合して選ぶ。行を選択すると表示する下位行が切り替わるため、別の構成・明細の行も選択してチェック状態を確認する。 手順6：「摘要」を押し、新期間X～Yの表示を確認する。新期間の支払回数・月を準備表に設定する。 手順7：MCM1005Uで「登録」を押し、「登録を実施します。よろしいですか？」の「OK」を押す。「登録が完了しました。」の通知を確認する。 手順8：MCM1005Uの「閉じる」を押してMCM1003Uへ戻り、記録した契約NOで「検索」を押す。「契約NO」リンクを押し、開始日で識別した期間タブを選び直す。 手順9：旧→新の期間タブと上段「次回更新日」を記録し、DB担当者にID・件数・日付を照合してもらう。 | G18: ・旧期間は開始～Eと旧機器・価格のまま、新期間はX～YとBを表示する。次回更新日はYの翌日。旧終了Eと新開始Xの間に空白・重複がない。 ・旧期間ID・旧明細値を維持し、新しい有効期間が1件増える。新明細は新期間ID所属。親契約の次回更新日はY+1日。 | H18: －（表示文言のみの確認は単体に委ねる） | P18: =IF(M18<>"",M18,IF(I18<>"",I18,"未実施")) -> 未実施 | Q18: 関連単体：1006-25 単体の表示・単独操作ではなく、期待結果の連携部分を追加判定。 根拠：R1005 / R1006 元Excel行：18。実施区分：通常＋DB担当者の読取確認。元の画面間フロー：1005U→1006U→1005U。
A19: INT01-10 | B19: 正常系 | C19: 変更途中で戻った場合の親データ保護 | D19: 1005U→1006U→1005U | E19: 【用意するもの】同じ初期状態にある試験用契約を閉じる条件Aと前へ条件Bで別々に用意する。機器変更が可能で、保存済み上段備考は「INT01-10保存済」。 【準備】機器と価格・件数を記録する。試験開始時の上段「備考」は保存済み文字「INT01-10保存済」。未保存文字の入力は操作手順3で1回だけ行う。ブラウザーの離脱確認が表示される環境は、使用ブラウザーの「離脱を確定する選択肢」の実表示名を開始前記録欄に記入する。 【入力値】上段備考＝INT01-10未保存。変更日とBは準備表へ記入。 【全ケース共通】試験専用の環境・データを使用。接続先と実行日／月を記録し、画面の識別番号（ID）・変更前情報を控える。DBの確認は担当者に読取だけを依頼し、自分で書き換えない。 | F19: 手順1：メニューの「取引先見積・契約検索」を押してMCM1003Uを開く。「契約NO」にデータ準備表の各条件の契約の契約NOを入力し、「検索」を押す。状態・承認状態のチェックは各条件の契約の状態を含める。 手順2：検索結果の「契約NO」「取引先名」「サポートID」「プラント名」が各条件の契約と一致する行の「契約NO」リンクを押す。MCM1005U「取引先契約内容」が開く。 手順3：上段「備考」を未保存文字にする。指定期間の「変更摘要開始日」に準備日を入力して「変更」を押す。1006U①で見積を選び「次へ」を押す。 手順4：MCM1006U②の左上「≪機器構成パターン≫」、右上「≪納入機器明細≫」、下段「≪機器個体・明細≫」で、未保存の新機器Bを選定する。選定する行のチェックをONにし、除外する行をOFFにする。品名・型式・個体名・シリアル番号と「見積依頼NO」を準備表と照合して選ぶ。行を選択すると表示する下位行が切り替わるため、別の構成・明細の行も選択してチェック状態を確認する。 手順5：条件A：1006U②の「閉じる」を押す。条件B：②の「前へ」を押して①を確認し、その後①の「閉じる」を押す。どちらも「摘要」は押さない。離脱確認が出た場合は開始前に記録した離脱確定の選択肢を押す。 手順6：戻った1005Uの上段「備考」、期間、機器・価格を記録する。「登録」は押さない。 手順7：DB担当者に処理前後の保存備考・期間・機器・価格・件数を照合してもらう。実施後は1005Uも登録せず閉じ、試験前の保存値から次条件を開始する。 | G19: ・②「前へ」の直後は①、②又は①「閉じる」の後は呼出元1005U。摘要していないBは親の機器情報に反映されず、旧機器・価格・期間を保持する。 ・1005Uに戻った上段備考は未保存文字「INT01-10未保存」。別契約の備考へ置き換わらない。 ・保存済み備考は「INT01-10保存済」のまま。契約・期間・機器・単価の件数と保存値は処理前のまま。Web上の未保存備考保持を、DB保存成功と判定しない。 | H19: －（表示文言のみの確認は単体に委ねる） | P19: =IF(M19<>"",M19,IF(I19<>"",I19,"未実施")) -> 未実施 | Q19: 関連単体：1006-22, 1006-25 単体の表示・単独操作ではなく、期待結果の連携部分を追加判定。 根拠：R1005 / R1006 「戻る」を実ボタン「前へ」に訂正。ブラウザー固有の確認文言はソースから確定できないため使用環境で記録。 元Excel行：19。実施区分：通常＋DB担当者の読取確認。元の画面間フロー：1005U→1006U→1005U。
A20: INT01-11 | B20: 正常系 | C20: 選定を戻って変更した後は最終案だけ保存 | D20: 1006U1/U2→1005U | E20: 【用意するもの】同じ取引先・プラントの未契約見積A／B。機器・個体・単価が別。 【準備】初回選定案はA、最終案はB。元ID・表示値を控える。登録する新規契約NOは、管理者が試験専用の未使用番号を準備表へ記入する。DBの契約ID採番と画面の契約NOは別。契約NOが自動設定されると仮定しない。 【入力値】準備表に実際の番号・名称・日付・値を記入する。 【全ケース共通】試験専用の環境・データを使用。接続先と実行日／月を記録し、画面の識別番号（ID）・変更前情報を控える。DBの確認は担当者に読取だけを依頼し、自分で書き換えない。 | F20: 手順1：メニューの「取引先見積・契約検索」を押してMCM1003Uを開く。「見積依頼NO」にデータ準備表の見積AのNOを入力し、「検索」を押す。状態・承認状態のチェックは見積Aの状態を含める。 手順2：検索結果で見積Aの「依頼NO」「取引先名」「サポートID」「プラント名」を照合し、右端の2つの「契約」列のうち左側にあるリンクを押す。MCM1006U①が開く。右側の破棄リンクは押さない。 手順3：1006U①でAだけONにして「次へ」を押す。②でAの構成・明細・個体を選定するが「摘要」は押さない。 手順4：②「前へ」を押す。①でAをOFF、BをONにして「次へ」を押す。 手順5：MCM1006U②の左上「≪機器構成パターン≫」、右上「≪納入機器明細≫」、下段「≪機器個体・明細≫」で、B由来の機器のみを選定する。選定する行のチェックをONにし、除外する行をOFFにする。品名・型式・個体名・シリアル番号と「見積依頼NO」を準備表と照合して選ぶ。行を選択すると表示する下位行が切り替わるため、別の構成・明細の行も選択してチェック状態を確認する。 手順6：「摘要」を押し、1005UにBが表示されAが表示されないことを確認する。 手順7：MCM1005U上段「契約NO」と期間内「契約NO」に準備した未使用の試験契約NOを入力する。「≪支払情報≫」で準備表の回数・月を設定する。開始月はON、回数はON月数以上。指定がない場合は回数1・開始月だけONにする。MCM1005Uで「登録」を押す。新規登録時の個体期限設定確認が表示された場合は「OK」、続く「登録を実施します。よろしいですか？」は「OK」を押す。「登録が完了しました。」の通知を確認する。 手順8：契約NOを記録する。MCM1005Uの「閉じる」を押してMCM1003Uへ戻り、記録した契約NOで「検索」を押す。「契約NO」リンクを押し、開始日で識別した期間タブを選び直す。 手順9：DB担当者に最終採用元・数量・価格を照合してもらう。 | G20: ・開き直した契約にはBの品名・型式・数量・金額が表示される。A由来の機器・数量・価格が残らない。 ・採用する構成・明細・個体・単価の元IDはB。A由来の保存行0件。仮のA選定案は独立した契約・期間として保存されない。 | H20: －（表示文言のみの確認は単体に委ねる） | P20: =IF(M20<>"",M20,IF(I20<>"",I20,"未実施")) -> 未実施 | Q20: 関連単体：1006-22, 1006-24 単体の表示・単独操作ではなく、期待結果の連携部分を追加判定。 根拠：R1006 / R1005 元Excel行：20。実施区分：通常＋DB担当者の読取確認。元の画面間フロー：1006U1/U2→1005U。
A21: INT01-12 | B21: 正常系 | C21: 未登録の新規選定を終了した際の孤立データ防止 | D21: 1006U→1005U→1003U | E21: 【用意するもの】契約未作成の見積A。 【準備】処理前の関連契約・期間・機器親子・単価件数をDB担当者が元見積IDで記録する。ブラウザー離脱確認の回答名は開始前に記録する。 【入力値】準備表に実際の番号・名称・日付・値を記入する。 【全ケース共通】試験専用の環境・データを使用。接続先と実行日／月を記録し、画面の識別番号（ID）・変更前情報を控える。DBの確認は担当者に読取だけを依頼し、自分で書き換えない。 | F21: 手順1：メニューの「取引先見積・契約検索」を押してMCM1003Uを開く。「見積依頼NO」にデータ準備表の見積AのNOを入力し、「検索」を押す。状態・承認状態のチェックは見積Aの状態を含める。 手順2：検索結果で見積Aの「依頼NO」「取引先名」「サポートID」「プラント名」を照合し、右端の2つの「契約」列のうち左側にあるリンクを押す。MCM1006U①が開く。右側の破棄リンクは押さない。 手順3：1006U①でAをONにし、準備期間で「次へ」を押す。 手順4：MCM1006U②の左上「≪機器構成パターン≫」、右上「≪納入機器明細≫」、下段「≪機器個体・明細≫」で、データ準備表の採用機器を選定する。選定する行のチェックをONにし、除外する行をOFFにする。品名・型式・個体名・シリアル番号と「見積依頼NO」を準備表と照合して選ぶ。行を選択すると表示する下位行が切り替わるため、別の構成・明細の行も選択してチェック状態を確認する。 手順5：「摘要」を押して1005Uを開く。上段契約NO・機器情報を画面記録するが「登録」「契約発行」「申請」は押さない。 手順6：1005Uの「閉じる」を押す。離脱確認が出る場合は記録した離脱確定の選択肢を押す。 手順7：1003U「見積依頼NO」で元見積Aを再検索する。DB担当者に元見積IDで追加契約と孤立親子の件数を照合してもらう。 | G21: ・再検索の元見積行は処理前の状態。未登録案の新しい契約NOが確定した契約として表示されない。 ・元見積に関連する契約・期間・構成・明細・個体・単価の件数増分がすべて0。親を持たない子データの追加0件。既存元見積の値・状態が処理前のまま。 | H21: 登録・発行・申請の完了通知なし。 | P21: =IF(M21<>"",M21,IF(I21<>"",I21,"未実施")) -> 未実施 | Q21: 関連単体：1006-24 単体の表示・単独操作ではなく、期待結果の連携部分を追加判定。 根拠：R1006 / R1005 元Excel行：21。実施区分：通常＋DB担当者の読取確認。元の画面間フロー：1006U→1005U→1003U。
A22: INT01-13 | B22: 正常系 | C22: 未保存の変更を契約発行前に保存 | D22: 1005U→1003P→1003U | E22: 【用意するもの】最新の現在又は未承認未来期間を編集できる契約A。審査中・承認中ではなく、対象期間に承認済み添付なし。契約発行が活性。契約時間帯は保存値1。支払・点検回数とON月は正常。 【準備】DB担当者が対象期間ID、KEIYAKUJIKANTAI=1、価格・機器・添付状態を記録する。帳票に転記されない任意備考を試験項目にしない。 【入力値】期間内「契約時間帯」＝2。 【全ケース共通】試験専用の環境・データを使用。接続先と実行日／月を記録し、画面の識別番号（ID）・変更前情報を控える。DBの確認は担当者に読取だけを依頼し、自分で書き換えない。 | F22: 手順1：メニューの「取引先見積・契約検索」を押してMCM1003Uを開く。「契約NO」にデータ準備表の契約Aの契約NOを入力し、「検索」を押す。状態・承認状態のチェックは契約Aの状態を含める。 手順2：検索結果の「契約NO」「取引先名」「サポートID」「プラント名」が契約Aと一致する行の「契約NO」リンクを押す。MCM1005U「取引先契約内容」が開く。 手順3：指定期間タブを選び、期間の右側「契約時間帯」を1から2へ変更する。「登録」は押さない。 手順4：「契約発行」を押す。「登録を実施します。よろしいですか？」の「OK」を押す。 手順5：取得した「契約手続依頼書.xls」を開き、契約セクションの契約時間帯（C14）を確認する。 手順6：MCM1005Uの「閉じる」を押してMCM1003Uへ戻り、記録した契約NOで「検索」を押す。「契約NO」リンクを押し、開始日で識別した期間タブを選び直す。 手順7：DB担当者に対象期間IDの契約時間帯を照合してもらう。 | G22: ・再表示した同じ期間の「契約時間帯」は2。対象期間の開始・終了日は処理前と同じで、別期間の契約時間帯は更新しない。 ・契約手続依頼書C14は「2H」。未保存の変更2が出力に使われ、旧値1Hのままにならない。 ・MCM_TK_KIKAN.KEIYAKUJIKANTAIは対象期間だけ2。機器・価格・対象外期間の契約時間帯は処理前のまま。 | H22: 契約発行前の登録確認「登録を実施します。よろしいですか？」→OK→「登録が完了しました。」→ファイル取得。 | P22: =IF(M22<>"",M22,IF(I22<>"",I22,"未実施")) -> 未実施 | Q22: 関連単体：1005-17, 1005-23 単体の表示・単独操作ではなく、期待結果の連携部分を追加判定。 根拠：R1005 帳票C14はMcm1003pConstantsと1-basedセル書込みで確認。 元Excel行：22。実施区分：通常＋DB担当者の読取確認。元の画面間フロー：1005U→1003P→1003U。
A23: INT01-14 | B23: 正常系 | C23: 帳票に新規・増減・継続機器を出し分け | D23: 1005U→1003P | E23: 【用意するもの】旧期間と比較する現在期間の契約Aと、変更日Xからの更新元見積。出精値引き0。未承認の現在期間から変更し、旧有効期間を残す。 【準備】新期間終了Yを準備表に記入し、変更開始Xから1年以内で元見積がX～Yを覆うよう用意する。機器別に旧→新を準備：新規A0→2、解除B2→0、増加C3→5、減少D5→3、継続E2→2。構成・明細・個体の管理番号とON/OFFを記録する。採用構成の名称・セット数・手配製番を旧新で記録し、採用個体の一次納入日・延長契約日を空欄／入力済みで用意する。異なる元見積NO、重複する手配製番、空の手配製番、点検回数とON月を準備する。実画面で直接編集できない属性は元見積・マスタの試験データとして準備し、選定画面の表示から記録する。 【入力値】準備表に実際の番号・名称・日付・値を記入する。 【全ケース共通】試験専用の環境・データを使用。接続先と実行日／月を記録し、画面の識別番号（ID）・変更前情報を控える。DBの確認は担当者に読取だけを依頼し、自分で書き換えない。 | F23: 手順1：メニューの「取引先見積・契約検索」を押してMCM1003Uを開く。「契約NO」にデータ準備表の契約Aの契約NOを入力し、「検索」を押す。状態・承認状態のチェックは契約Aの状態を含める。 手順2：検索結果の「契約NO」「取引先名」「サポートID」「プラント名」が契約Aと一致する行の「契約NO」リンクを押す。MCM1005U「取引先契約内容」が開く。 手順3：旧期間タブで「変更摘要開始日」にXを入力し「変更」。1006U①「期間」の終了日に準備表のYを入力し、X～Yを覆う更新元見積だけを選んで「次へ」。 手順4：MCM1006U②の左上「≪機器構成パターン≫」、右上「≪納入機器明細≫」、下段「≪機器個体・明細≫」で、A・C・D・Eを選定する。選定する行のチェックをONにし、除外する行をOFFにする。BのチェックをOFFにし、採用個体の数量合計を準備表どおりにする。品名・型式・個体名・シリアル番号と「見積依頼NO」を準備表と照合して選ぶ。行を選択すると表示する下位行が切り替わるため、別の構成・明細の行も選択してチェック状態を確認する。 手順5：「摘要」を押す。1005Uの新期間で点検回数とON月、支払回数とON月を準備表に設定する。 手順6：MCM1005Uで「登録」を押し、「登録を実施します。よろしいですか？」の「OK」を押す。「登録が完了しました。」の通知を確認する。 手順7：選択期間を変えずに「契約発行」を押す。未保存の場合は登録確認の「OK」を押す。取得した「契約手続依頼書.xls」を開いて、Excelの表示・印刷レイアウトだけでなく、下記の転記内容を確認する。 手順8：MCM1005Uの「閉じる」を押してMCM1003Uへ戻り、記録した契約NOで「検索」を押す。「契約NO」リンクを押し、開始日で識別した期間タブを選び直す。 手順9：旧新タブの機器・数量・価格を比較し、DB担当者に選定差分と帳票行の対応を照合してもらう。 | G23: ・新期間の機器情報にはA2・C5・D3・E2が表示され、Bは表示されない。旧期間の数量は元のまま。金額は各採用単価×新数量の準備計算値。 ・帳票の機器別数量・備考区分は、A＝数量2「契約」、B＝数量2「解約」、C＝数量3「契約(継続）」＋数量2「契約」、D＝数量3「契約(継続）」＋数量2「解約」、E＝数量2「契約(継続）」。同じ継続分を重複計上しない。 ・帳票の点検回数・対象月は登録した新設定。元見積NOは採用した番号だけで重複なし、手配製番は採用した空欄以外を重複なしで連結する。日付空欄を架空の日付にしない。 ・OFF→ONは選択した新期間IDと該当構成・明細IDの配下に追加、ON→OFFは新期間の対象解除、ON→ONは準備した数量・構成名称・セット数・手配製番・個体日付に一致する。旧期間の行・属性・単価は変更前のまま。元見積と個体管理の関連が保持される。 | H23: －（表示文言のみの確認は単体に委ねる） | P23: =IF(M23<>"",M23,IF(I23<>"",I23,"未実施")) -> 未実施 | Q23: 関連単体：1005-23 単体の表示・単独操作ではなく、期待結果の連携部分を追加判定。 根拠：R1005 、VB1005-21/23/24 点検親子追加・削除の判定は29。帳票書式だけの単体項目は追加せず、保存差分と出力区分の連携を確認する。 元Excel行：23。実施区分：通常＋DB担当者の読取確認。元の画面間フロー：1005U→1003P。
A24: INT01-15 | B24: 正常系 | C24: 解約日を登録した契約発行の内容 | D24: 1005U→1003P→3002U | E24: 【用意するもの】状態が契約、承認状態が承認済で、上段「解約日」を入力できる契約A。対象期間に承認済添付が1件以上あり、契約発行が活性。解約日未設定。 【準備】解約日Kを月初日とし、Kより前の支払月、K当日、Kより後の支払月が抽出条件を満たす専用データを用意する。例K=2027/01/01、比較月2026/12・2027/01・2027/02。DB担当者が支払TSUKIの実日付とビュー採否を記録する。 【入力値】上段「解約日」＝K。比較する3つの年月の支払い月・年払い／月払いは準備表に記入。 【全ケース共通】試験専用の環境・データを使用。接続先と実行日／月を記録し、画面の識別番号（ID）・変更前情報を控える。DBの確認は担当者に読取だけを依頼し、自分で書き換えない。 | F24: 手順1：メニューの「取引先見積・契約検索」を押してMCM1003Uを開く。「契約NO」にデータ準備表の契約Aの契約NOを入力し、「検索」を押す。状態・承認状態のチェックは契約Aの状態を含める。 手順2：検索結果の「契約NO」「取引先名」「サポートID」「プラント名」が契約Aと一致する行の「契約NO」リンクを押す。MCM1005U「取引先契約内容」が開く。 手順3：指定期間タブを選ぶ。上段の「解約日」にKを入力する。機器選定や期間変更は行わない。 手順4：MCM1005Uで「登録」を押し、「登録を実施します。よろしいですか？」の「OK」を押す。「登録が完了しました。」の通知を確認する。 手順5：選択期間を変えずに「契約発行」を押す。未保存の場合は登録確認の「OK」を押す。取得した「契約手続依頼書.xls」を開いて、Excelの表示・印刷レイアウトだけでなく、下記の転記内容を確認する。 手順6：MCM1005Uの「閉じる」を押してMCM1003Uへ戻り、記録した契約NOで「検索」を押す。「契約NO」リンクを押し、開始日で識別した期間タブを選び直す。 手順7：上段「解約日」と同期間の機器・価格を確認する。 手順8：確認した画面内容を記録し、現在の画面の「閉じる」を押す。戻り先が業務画面の場合はその画面の「閉じる」も押し、メニューまで戻る。離脱確認が出たら、開始前に記録した離脱確定の選択肢を押す。支払い明細出力指示（MCM3002U）をメニューから開く。「支払い月」に準備表の年月（yyyy/MM）を入力し、準備した支払回数に対応する「年払い」又は「月払い」を選んで「出力」を押す。ファイルを取得した場合はZIPを展開し、中の支払い明細と発注確認書のExcelを開く。抽出全体が0件なら「検索結果が1件も存在しません。」を記録し、ファイルを開く操作は行わない。各条件の対象契約NO・取引先・対象月で行を識別する。 手順9：比較月3回を別々に出力し、対象契約の採否と価格をDB担当者の抽出結果と照合する。 | G24: ・再表示の解約日はK。対象期間の開始・終了日、機器・価格・承認済添付は準備した処理前値のまま。 ・契約手続依頼書の区分は解約、解約日C19はK、解約の仕切金額C18は選択期間の仕切合計。明細は対象期間の機器を「解約」区分で出す。新規契約セクションに新規金額を追加しない。 ・支払明細日付TSUKI≦Kは他の条件を満たせば対象、TSUKI>Kは対象契約の行0件。月だけでK当日と判定せず、DBの実日付で比較する。 ・Kより後の比較月に他契約を含む抽出全体が0件なら、「検索結果が1件も存在しません。」とファイル取得0件を確認する。対象契約が出ないことはDBの対象契約IDでも照合する。他契約の結果がある場合はExcel内の対象契約行0件で判定する。 ・MCM_TK_KEIYAKU.KAIYAKU_DT=K、期間・旧機器・単価・承認済添付の所属は処理前のまま。支払ビューはTSUKIとKの比較で採否が準備表に一致する。元支払履歴の行を削除しない。 | H24: －（表示文言のみの確認は単体に委ねる） | P24: =IF(M24<>"",M24,IF(I24<>"",I24,"未実施")) -> 未実施 | Q24: 関連単体：1005-3, 1005-23, 1005-24 単体の表示・単独操作ではなく、期待結果の連携部分を追加判定。 根拠：R1005 / R3002 実施前にQ04の条件・期待を確認。 Q04は本ケースの解約日入力・登録・発行の経路をソースで具体化。解約申請→審査承認→契約状態「解約」への完了手続はこの操作に含めない。Q11／Q16の配備ビューが未確認なら支払部分は保留。 元Excel行：24。実施区分：通常＋DB担当者の読取確認。元の画面間フロー：1005U→1003P→3002U。
A25: INT01-16 | B25: 正常系 | C25: 契約日程変更が点検と支払い予定に反映 | D25: 1005U→3002U/3003U | E25: 【用意するもの】最新の現在期間を変更できる契約Aと更新元見積。変更対象外の別契約B。出精値引き0。 【準備】期間途中の月初日Xで新期間を作る。旧・新期間それぞれに支払と点検の対象月を用意する。Bにも同月の予定を用意する。変更後終了Yを準備表へ記入し、X～Yを1年以内、更新元見積がX～Yを覆う条件にする。旧期間に残す対象月と新期間に設定する対象月、それぞれの機器・支払額・点検回数を準備表へ記入する。DB担当者がAの旧期間ID、支払親子・点検親子、ユーザー契約・確認済製番・点検対象個体を記録し、各出力ビューで対象となることを確認する。Q11／Q16未確認なら後続出力は保留。 【入力値】準備表に実際の番号・名称・日付・値を記入する。 【全ケース共通】試験専用の環境・データを使用。接続先と実行日／月を記録し、画面の識別番号（ID）・変更前情報を控える。DBの確認は担当者に読取だけを依頼し、自分で書き換えない。 | F25: 手順1：メニューの「取引先見積・契約検索」を押してMCM1003Uを開く。「契約NO」にデータ準備表の契約Aの契約NOを入力し、「検索」を押す。状態・承認状態のチェックは契約Aの状態を含める。 手順2：検索結果の「契約NO」「取引先名」「サポートID」「プラント名」が契約Aと一致する行の「契約NO」リンクを押す。MCM1005U「取引先契約内容」が開く。 手順3：現在期間のタブを選び、「変更摘要開始日」にXを入力して「変更」を押す。MCM1006U①が開くことを確認する。 手順4：1006U①で開始日Xを確認し、終了日に準備したYを入力する。X～Yを覆う更新元見積だけをONにして「次へ」を押す。 手順5：MCM1006U②の左上「≪機器構成パターン≫」、右上「≪納入機器明細≫」、下段「≪機器個体・明細≫」で、新期間の予定対象機器を選定する。選定する行のチェックをONにし、除外する行をOFFにする。品名・型式・個体名・シリアル番号と「見積依頼NO」を準備表と照合して選ぶ。行を選択すると表示する下位行が切り替わるため、別の構成・明細の行も選択してチェック状態を確認する。 手順6：「摘要」を押す。1005U新期間の「≪点検情報≫」で機器行の「回数」と指定月チェック、「≪支払情報≫」の「回数」と月チェックを準備表に設定する。 手順7：MCM1005Uで「登録」を押し、「登録を実施します。よろしいですか？」の「OK」を押す。「登録が完了しました。」の通知を確認する。 手順8：MCM1005Uの「閉じる」を押してMCM1003Uへ戻り、記録した契約NOで「検索」を押す。「契約NO」リンクを押し、開始日で識別した期間タブを選び直す。 手順9：旧新タブの期間と点検・支払のON月を比較する。 手順10：確認した画面内容を記録し、現在の画面の「閉じる」を押す。戻り先が業務画面の場合はその画面の「閉じる」も押し、メニューまで戻る。離脱確認が出たら、開始前に記録した離脱確定の選択肢を押す。支払い明細出力指示（MCM3002U）をメニューから開く。「支払い月」に準備表の年月（yyyy/MM）を入力し、準備した支払回数に対応する「年払い」又は「月払い」を選んで「出力」を押す。取得したZIPを展開し、中の支払い明細と発注確認書のExcelを開く。各条件の対象契約NO・取引先・対象月で行を識別する。 手順11：確認した画面内容を記録し、現在の画面の「閉じる」を押す。戻り先が業務画面の場合はその画面の「閉じる」も押し、メニューまで戻る。離脱確認が出たら、開始前に記録した離脱確定の選択肢を押す。メニューの「保守点検出力指示」を押してMCM3003Uを開く。「点検対象月」の左欄と右欄に同じ対象年月（yyyy/MM）を入力し、「全件出力」を選ぶ。「作業用リスト出力」を押し、取得した定期点検リストのExcelを開く。「ＤＢ登録用データ」は本ケースでは押さない。 手順12：変更前月と後月をそれぞれ出力する。DB担当者が採用期間ID・予定月を照合する。 | G25: ・旧終了はX−1日、新開始はX、指定した新終了を表示する。新タブの点検・支払ON月は入力値、旧タブは旧設定。 ・支払い明細と定期点検リストのAの機器・金額・対象月は、その月に採用される旧又は新期間の準備値に一致する。新期間外の予定を新期間の行として出さない。Bの行・予定は処理前のまま。 ・旧新期間所属のMCM_TK_SIHARAI／MCM_TK_SIHARAIMEISAI、MCM_TK_TENKEN／MCM_TK_TENKENMEISAIの親キー・対象月が登録値と一致する。他期間・Bの予定を新期間IDへ付け替えない。 | H25: －（表示文言のみの確認は単体に委ねる） | P25: =IF(M25<>"",M25,IF(I25<>"",I25,"未実施")) -> 未実施 | Q25: 関連単体：1005-13, 1005-14, 1005-15 単体の表示・単独操作ではなく、期待結果の連携部分を追加判定。 根拠：R1005 / R3002 / R3003 1005Uの読取専用「期間」欄を直接変更させない。3002U／3003Uの検索結果一覧を仮定せず、実際の出力操作を記載。 元Excel行：25。実施区分：通常＋DB担当者の読取確認。元の画面間フロー：1005U→3002U/3003U。
A26: INT01-17 | B26: 正常系 | C26: 期間を切り替えても添付と帳票のキーが一致 | D26: 1005U→1003P/添付 | E26: 【用意するもの】過去期間と最新の編集可能期間を持つ契約A。各期間に別名・別内容の添付を用意し、実ファイルを取得できることを管理者が確認する。発行確認用の最新期間には承認済添付を置かない。 【準備】契約NO旧N0と未使用の新N1、全期間の契約NO保持値・添付ID・保存パス・内容・機器・金額を記録する。過去期間の契約発行は禁止される状態なら、添付の取得だけを確認し、最新期間で発行する。 【入力値】上段契約NO＝準備した未使用N1（50桁以内）。添付は試験用複製。 【全ケース共通】試験専用の環境・データを使用。接続先と実行日／月を記録し、画面の識別番号（ID）・変更前情報を控える。DBの確認は担当者に読取だけを依頼し、自分で書き換えない。 | F26: 手順1：メニューの「取引先見積・契約検索」を押してMCM1003Uを開く。「契約NO」にデータ準備表の契約Aの契約NOを入力し、「検索」を押す。状態・承認状態のチェックは契約Aの状態を含める。 手順2：検索結果の「契約NO」「取引先名」「サポートID」「プラント名」が契約Aと一致する行の「契約NO」リンクを押す。MCM1005U「取引先契約内容」が開く。 手順3：過去期間タブを選び、「≪添付資料≫」の記録した「ファイル名」リンクを押す。取得したファイルを対応アプリで開き、準備した過去用内容を比較する。 手順4：最新期間タブに切り替え、最新用「ファイル名」リンクから取得して内容を比較する。ブラウザーのダウンロードを経由する。 手順5：上段「契約NO」をN0からN1に変更し、別の欄を選択して入力を確定する。各期間内「契約NO」がN1になるか記録する。期間欄を個別にN1へ手直しせず、同期の有無を記録する。全期間の確認後は最新期間のタブへ戻し、以後の登録・契約発行はそのタブで行う。 手順6：MCM1005Uで「登録」を押し、「登録を実施します。よろしいですか？」の「OK」を押す。「登録が完了しました。」の通知を確認する。 手順7：選択期間を変えずに「契約発行」を押す。未保存の場合は登録確認の「OK」を押す。取得した「契約手続依頼書.xls」を開いて、Excelの表示・印刷レイアウトだけでなく、下記の転記内容を確認する。 手順8：「閉じる」で戻り、1003Uの「契約NO」にN1を入力して検索し、リンクを開き直す。過去→最新のタブで契約NO・期間・機器・添付を記録する。 手順9：DB担当者が全期間の契約NOと添付の所属・パスを照合する。 | G26: ・VBの契約NO同期仕様では上段と各期間の契約NOはN1。N0のままの期間があれば同期判定はNGとし、添付取得の判定と分けて記録する。各期間の機器・数量・金額は変更前のまま。 ・過去添付は準備した過去内容、最新添付は最新内容。取得内容が別期間のファイルに置き換わらない。 ・最新期間の契約手続依頼書はN1と最新期間の機器・仕切合計を使用する。過去期間の金額・機器を混入させない。 ・MCM_TK_KEIYAKU.KEIYAKU_NOと全期間のKEIYAKU_NOはN1。MCM_TK_TENPU.TK_KIKAN_IDと既存DIRECTORY・承認状態は処理前のまま。既存ファイルの移動・改名を自動期待しない。 | H26: －（表示文言のみの確認は単体に委ねる） | P26: =IF(M26<>"",M26,IF(I26<>"",I26,"未実施")) -> 未実施 | Q26: 関連単体：1005-19, 1005-23 単体の表示・単独操作ではなく、期待結果の連携部分を追加判定。 根拠：R1005 、VB1005-29 契約NO同期の元根拠：VB Screen KEIYAKU_NOTextBox.Leaveで全タブへ代入。Webは親と期間を別々に更新しており、自動同期がない実装差異候補。期待をWebの現状へ変えず、操作して独立に結果記録する。Q02未解消なら添付取得は保留。 元Excel行：26。実施区分：通常＋DB担当者の読取確認。元の画面間フロー：1005U→1003P/添付。
A27: INT01-18 | B27: 仕様照合 | C27: 重複機器で次画面・親契約への反映を中止 | D27: 1006U1/U2→1005U | E27: 【用意するもの】同じプラントの見積A／Bに、機器明細IDと個体管理IDの組が同じ行を1組以上含める。個体名だけの一致で準備しない。 【準備】新規契約モードで実施し、元見積から契約が未作成であることと関連親子件数を記録する。既存契約からも確認する場合は別パターンを用意し、処理前の機器・価格・期間を記録する。1006U①で選ぶ2行は、別の依頼NOの行でも同じ依頼NOの異なる「時間」の行でもよい。元見積契約時間ID2件がそれぞれ選択できることを確認する。期間は開始日あり・終了日あり・開始≦終了・1年以内とし、重複個体検査より前の日付エラーを避ける。 【入力値】準備表に実際の番号・名称・日付・値を記入する。 【全ケース共通】試験専用の環境・データを使用。接続先と実行日／月を記録し、画面の識別番号（ID）・変更前情報を控える。DBの確認は担当者に読取だけを依頼し、自分で書き換えない。 | F27: 手順1：メニューの「取引先見積・契約検索」を押してMCM1003Uを開く。「見積依頼NO」にデータ準備表の見積AのNOを入力し、「検索」を押す。状態・承認状態のチェックは見積Aの状態を含める。 手順2：検索結果で見積Aの「依頼NO」「取引先名」「サポートID」「プラント名」を照合し、右端の2つの「契約」列のうち左側にあるリンクを押す。MCM1006U①が開く。右側の破棄リンクは押さない。 手順3：1006U①「≪見積情報≫」で依頼NOと「時間」を準備表と照合し、重複個体を含む見積契約時間2行をONにする。準備した1年以内の期間を入力して「次へ」を押す。 手順4：「選択した見積内に重複した機器が存在します。」を確認して「OK」を押す。①に留まることを記録する。 手順5：「閉じる」で起点へ戻る。元見積を再検索し、DB担当者に関連親子件数を比較してもらう。既存契約パターンでは契約NOから1005Uを開いて旧機器・価格・期間を比較する。 | G27: ・通知後に1006U②へ進まない。新規契約の1005Uを新しく確定表示しない。既存契約の場合は旧機器・数量・金額・期間を維持する。 ・新規なら元見積関連の契約・期間・機器・単価増分0。既存なら親子件数・値が処理前のまま。例外通知後に処理続行して機器・単価を保存しない。 | H27: MSG_0038E「選択した見積内に重複した機器が存在します。」。「次へ」押下後、画面通知のOKで閉じる。 | P27: =IF(M27<>"",M27,IF(I27<>"",I27,"未実施")) -> 未実施 | Q27: 関連単体：1006-8 単体の表示・単独操作ではなく、期待結果の連携部分を追加判定。 根拠：R1006 nextButton_Click、共通C06、VB1006-03 元の同一機器という表現を、重複検出キーの組へ具体化。新規・既存の未変更確認を区別。 元Excel行：27。実施区分：通常＋DB担当者の読取確認。元の画面間フロー：1006U1/U2→1005U。
A28: INT01-19 | B28: 仕様照合 | C28: 下位チェック不足で親契約への摘要を中止 | D28: 1006U2→1005U | E28: 【用意するもの】未契約見積から1006U②へ到達できる試験用データ。構成・明細・個体を1組選定できること。 【準備】関連DB件数を事前記録する。19-Aは通常UIの全解除。19-Bは明細だけ0件、19-Cは個体だけ0件の技術確認。Webはチェックが親子連動するためB／Cは付録Aの開発者操作を用い、通常作業者は単独で行わない。 【入力値】A：構成0／明細0／個体0、B：構成1以上／明細0／個体1以上、C：構成1以上／明細1以上／個体0。 【全ケース共通】試験専用の環境・データを使用。接続先と実行日／月を記録し、画面の識別番号（ID）・変更前情報を控える。DBの確認は担当者に読取だけを依頼し、自分で書き換えない。 | F28: 手順1：メニューの「取引先見積・契約検索」を押してMCM1003Uを開く。「見積依頼NO」にデータ準備表の見積AのNOを入力し、「検索」を押す。状態・承認状態のチェックは見積Aの状態を含める。 手順2：検索結果で見積Aの「依頼NO」「取引先名」「サポートID」「プラント名」を照合し、右端の2つの「契約」列のうち左側にあるリンクを押す。MCM1006U①が開く。右側の破棄リンクは押さない。 手順3：1006U①で見積AをONにして「次へ」を押す。 手順4：19-A：②「≪機器構成パターン≫」の全行チェックをOFFにし、明細・個体もOFFになったことを確認する。19-B／C：開発者が付録Aの指定パターンでチェック状態を作り、表とチェック件数を記録する。 手順5：②「摘要」を押す。「見積依頼する機器を選定してください。」の通知を確認して「OK」を押す。 手順6：②に留まることを確認し、「閉じる」で起点へ戻る。元見積を再検索しDB担当者に件数・元値を確認してもらう。 手順7：次パターンは①から開き直して構成・明細・個体が各1組以上ONの選定状態を作り直す。前パターンの書換え状態を引き継がない。 | G28: ・3パターンとも摘要で1005Uへ選定値を反映せず、1006U②に留まる。既存契約を起点にする追加確認では旧期間・旧機器・数量を維持する。 ・契約・期間・構成・明細・個体・単価の増分0。既存の場合は件数・価格・期間が処理前のまま。 | H28: MSG_0023E「見積依頼する機器を選定してください。」。摘要後の通知をOKで閉じる。 | P28: =IF(M28<>"",M28,IF(I28<>"",I28,"未実施")) -> 未実施 | Q28: 関連単体：1006-23 単体の表示・単独操作ではなく、期待結果の連携部分を追加判定。 根拠：R1006 tekiyoButton_Click、共通C06、VB1006-10 親子連動を無視してB／Cを通常UIで作れると記載しない。技術確認の操作を付録Aに全文記載。 元Excel行：28。実施区分：19-A通常、19-B／C開発者支援＋DB読取。元の画面間フロー：1006U2→1005U。
... A39: INT01-30 | B39: 異常系 | C39: MCM1011U(審査・承認（取引先契約）)：点検・支払の入力に誤りがある場合に、契約発行と申請が確定されないこと | D39: 1005U→1003P/1011U | E39: 【確認すること】 点検や支払の「回数」と「月のチェック」が合っていないとき、「契約発行」「申請」が途中で止まり、何も保存・出力・申請されないこと。合っているときは、最後まで進めること。 【前提】 ・使用ユーザー：取引先契約内容(MCM1005U)の更新権限を持つユーザー ・保有権限：取引先契約機能の更新作成権限 ・必要な登録済みデータ：契約A（1件） - 状態＝契約、承認状態＝作成中または差戻中 - 最新の期間が、現在の期間または開始日が未来で未承認の期間である（承認済みの添付がない） - その期間に、作成中の添付が1件ある - 点検情報と支払情報に行があり、回数と月を編集できる ・事前に控える値：契約Aの契約NO、対象期間の開始日・終了日、備考、点検の回数と月、支払の回数と月。審査・承認（取引先契約）(MCM1011U)で、契約AのサポートID・承認状態＝審査中で検索した件数 ・準備：契約手続依頼書の保存先に、空のフォルダを用意する（以前のファイルと区別するため）。DB担当者に、契約A・期間・点検・支払・添付の保存値を読取で控えてもらう ・開始時の画面状態：メニュー画面 ・対象外：期間の開始日が終了日より後、または同じ日になる誤りは、通常の画面操作では作れないため、開発者テストで別に確認する | F39: 【操作】 （1）契約Aを開く 1. メニューから「取引先見積・契約検索」を選択し、MCM1003U(取引先見積・契約検索)を開く。 2. 「契約NO」欄に契約Aの契約NOを入力し、「検索」を押下する。 3. 一覧の契約Aの行の「契約NO」リンクを押下する。MCM1005U(取引先契約内容)が開く。 4. 対象期間のタブを選択し、備考、点検の回数と月、支払の回数と月を控える。 （2）区分A：エラーまたは取消で止まることの確認（下の表の6回を、上から順に実施する） 5. 表の「設定」のとおりに、回数と月のチェックを変更する。点検は画面中ほどの≪点検情報≫の表の「回数」欄と1月～12月のチェック欄、支払は画面左下の≪支払情報≫の「回数」欄と1月～12月のチェック欄で変更する。表に無い項目は変更しない。 6. 画面上部の「備考」欄に、表の「備考の入力」を入力する。「登録」ボタンは押下しない。（備考を入力するのは、画面に変更がある状態にするため。変更が無いと入力チェックが動かず、契約手続依頼書がそのまま出力される。） 7. 画面右下の、表の「押すボタン」を押下する。 8. 表示されたメッセージ（文言、表示された場所）を控える。エラーの場合は「OK」を押下して閉じる。確認ダイアログが表示された場合は、表の「ダイアログの操作」のとおりに押下する。 9. 契約発行の回は契約手続依頼書の保存先を、申請の回はMCM1011Uの検索結果の件数を確認する。 10. MCM1005Uの「閉じる」を押下し、手順1～4でもう一度開く。離脱確認が表示された場合は、入力を破棄する側を押下する。備考、点検、支払が手順4で控えた値に戻っていることを確認する。 ③-発行｜設定：点検の回数＝1、月チェックを2か所ON（開始月と翌月）｜備考の入力：INT01-30-③-発行｜押すボタン：契約発行｜ダイアログの操作：なし ③-申請｜設定：③-発行と同じ｜備考の入力：INT01-30-③-申請｜押すボタン：申請｜ダイアログの操作：なし ④-発行｜設定：支払の回数＝1、月チェックを2か所ON（開始月と翌月）｜備考の入力：INT01-30-④-発行｜押すボタン：契約発行｜ダイアログの操作：なし ④-申請｜設定：④-発行と同じ｜備考の入力：INT01-30-④-申請｜押すボタン：申請｜ダイアログの操作：なし ⑤-発行｜設定：支払の回数＝1、開始月のチェックをOFF、別の月を1か所ON｜備考の入力：INT01-30-⑤-発行｜押すボタン：契約発行｜ダイアログの操作：「期間の開始月に支払チェックがされてません。処理を続行してもよろしいですか？」で「キャンセル」 ⑤-申請｜設定：⑤-発行と同じ｜備考の入力：INT01-30-⑤-申請｜押すボタン：申請｜ダイアログの操作：⑤-発行と同じ （3）区分B：正しい入力のとき最後まで進むことの確認（次の3回を、この順に実施する。申請をすると契約を編集できなくなるため、申請は最後にする） 11. 手順1～4で契約Aを開く。 12. ⑥-発行：点検の回数＝2、月チェックを2か所ON（開始月と翌月）に変更し、備考＝INT01-30-⑥-発行を入力する。「契約発行」を押下し、確認ダイアログ「登録を実施します。よろしいですか？」で「OK」を押下する。完了メッセージを控え、ダウンロードされた契約手続依頼書を開く。 13. ⑧-発行：もう一度契約Aを開き、支払の回数＝2、月チェックを2か所ON（開始月と翌月）に変更し、備考＝INT01-30-⑧-発行を入力する。手順12と同様に実施する。 14. ⑥-申請：もう一度契約Aを開き、備考＝INT01-30-⑥-申請を入力する（点検と支払は、手順12・13で登録した値のまま）。「申請」を押下し、確認ダイアログ「申請を実施します。よろしいですか？」で「OK」を押下する。完了メッセージを控える。 15. メニューから「取引先契約 審査・承認」を選択し、MCM1011U(審査・承認（取引先契約）)を開く。契約AのサポートID、承認状態＝審査中で「検索」を押下し、契約Aの行を確認する。 16. DB担当者に、事前の控えと同じSQLを実行してもらい、区分Aは事前と同じ、区分Bは入力どおりに保存されたことを確認してもらう。 【入力値】 ・契約A＝準備した契約の契約NO ・備考＝表のとおり（例：INT01-30-③-発行） ・点検／支払の回数・月のチェック＝表および手順12・13のとおり | G39: 【画面確認】 （区分A：6回とも） 1. ③では「点検回数と月のチェックの数が一致していません。」、④では「支払回数と月のチェックの数が一致していません。」のエラーが表示され、処理が中止されること。 2. ⑤では、確認ダイアログで「キャンセル」を押下すると、処理が中止され、MCM1005Uの画面に留まること。 3. いずれの回も、「登録を実施します。よろしいですか？」「申請を実施します。よろしいですか？」の確認ダイアログが表示されないこと。 4. 契約発行の回は、契約手続依頼書の保存先が空のままであること。 5. 申請の回は、MCM1011Uで承認状態＝審査中の件数が、事前に控えた件数から増えていないこと。 6. MCM1005Uをもう一度開くと、備考、点検、支払が事前に控えた値のままであること（入力した「INT01-30-…」の文字が残っていないこと）。 （区分B） 7. ⑥-発行、⑧-発行では、「登録が完了しました。」が表示され、契約手続依頼書が1件ダウンロードされること。 8. ⑥-申請では、「申請を完了しました。」または「申請が完了しました。」が表示されること。 9. ⑥-申請の後、MCM1011Uで承認状態＝審査中の件数が1件増え、契約Aの行が表示されること。 【ファイル確認】 1. ⑥-発行、⑧-発行の契約手続依頼書で、機器と見積金額（仕切）が、MCM1005Uの表示と同じであること。点検と支払の回数・月が、画面で登録した内容と同じであること。 2. ⑥-申請では、契約手続依頼書が新たにダウンロードされないこと。 【DB確認】 （区分A：6回とも） 対象テーブル＝MCM_TK_KEIYAKU、MCM_TK_KIKAN、MCM_TK_TENKEN／MCM_TK_TENKENMEISAI、MCM_TK_SIHARAI／MCM_TK_SIHARAIMEISAI、MCM_TK_TENPU、確認理由＝エラーや取消のとき、途中まで保存されていないことを確認するため。検索条件＝契約Aの契約ID・対象期間ID、対象カラム＝備考、点検・支払の回数と月、添付の承認状態、契約の承認状態、期待値＝事前に控えた値と同じであること。 （区分B） ・⑥-発行、⑧-発行の後：備考、点検の回数と月、支払の回数と月が、画面で入力した値で保存されていること。契約の承認状態が変わっていないこと。 ・⑥-申請の後：契約の承認状態が審査中になり、対象期間の作成中だった添付が審査中に更新されていること。他の契約の値・状態が変わっていないこと。 | H39: 1. 表示タイミング＝区分Aの③で「契約発行」または「申請」を押下した時 表示形式＝Web画面の通知（入力エラー） メッセージID＝MSG_0103E 表示文言＝点検回数と月のチェックの数が一致していません。 作業者の操作＝「OK」を押下して閉じる 2. 表示タイミング＝区分Aの④で「契約発行」または「申請」を押下した時 表示形式＝Web画面の通知（入力エラー） メッセージID＝MSG_0104E 表示文言＝支払回数と月のチェックの数が一致していません。 作業者の操作＝「OK」を押下して閉じる 3. 表示タイミング＝区分Aの⑤で「契約発行」または「申請」を押下した時 表示形式＝確認ダイアログ（OK/キャンセル） メッセージID＝MSG_0105G 表示文言＝期間の開始月に支払チェックがされてません。処理を続行してもよろしいですか？ 作業者の操作＝「キャンセル」を押下する 4. 表示タイミング＝区分Bの⑥-発行、⑧-発行で「契約発行」を押下した時、およびその完了時 表示形式＝確認ダイアログ（OK/キャンセル）、完了メッセージ メッセージID＝MSG_0007G（確認）、MSG_0008G（完了）（VB定義） 表示文言＝「登録を実施します。よろしいですか？」、「登録が完了しました。」 作業者の操作＝「OK」を押下する 5. 表示タイミング＝区分Bの⑥-申請で「申請」を押下した時、およびその完了時 表示形式＝確認ダイアログ（OK/キャンセル）、完了メッセージ メッセージID＝MSG_0120G（確認）、MSG_0121G（完了）（VB定義） 表示文言＝「申請を実施します。よろしいですか？」、「申請を完了しました。」または「申請が完了しました。」 作業者の操作＝「OK」を押下する | P39: =IF(M39<>"",M39,IF(I39<>"",I39,"未実施")) -> 未実施 | Q39: 関連単体：1005-13, 1005-14, 1005-15, 1005-16, 1005-23, 1005-26 単体の表示・単独操作ではなく、期待結果の連携部分を追加判定。 根拠：R1005 UpdButton・KeiyakuHakoButton_Click・SinseiButton_Click、VB1005-13/14/16/17、共通C06/C12 9条件は発行／申請を別判定。単体のエラー文言確認ではなく、保存・出力・申請を先行確定しない境界を判定する。18行の判定表を付録Cに記載。DB不正fixtureの準備権限がなければ①②を保留し、通常UIの入力手順を創作しない。 元Excel行：39。実施区分：①②開発者fixture＋DB読取、③～⑨通常＋DB読取。元の画面間フロー：1005U→1003P/1011U。
A40: INT01-31 | B40: 異常系 | C40: 契約済み見積の破棄拒否 | D40: 1003U→1005U | E40: 【用意するもの】「見積依頼機器選定」の作成権限を持つユーザー。新規登録後に契約を破棄した試験見積A。残る契約の状態は破棄、元見積契約時間の状態は見積。有効契約（状態が契約又は解約）の行では見積破棄リンクが非表示なので、その行を押下対象にしない。 【準備】準備で契約を破棄する担当者には「取引先契約内容」の作成権限も必要。見積破棄の実施者と準備担当者は別ユーザーでもよい。 準備は試験専用の通常契約で行う。過去支払月なしの未来期間を新規登録し、1003U右側「契約」列の「破棄」を実行する。DB担当者が契約親、最新有効期間、機器・個体・元単価の関連が残ることを確認する。1003Uを再検索して見積側「破棄」リンクが表示される行を用意する。 DB担当者が元見積契約時間ID・残る契約ID・画面の状態（破棄）・DB各状態・関連件数を記録する。配備ビューで該当行とリンクが確認できなければ保留。通常の契約済み行でリンクがあると推測したり、ブラウザーで非表示リンクを作ったりしない。 【入力値】準備表に実際の番号・名称・日付・値を記入する。 【全ケース共通】試験専用の環境・データを使用。接続先と実行日／月を記録し、画面の識別番号（ID）・変更前情報を控える。DBの確認は担当者に読取だけを依頼し、自分で書き換えない。 | F40: 手順1：メニュー「取引先見積・契約検索」から1003Uを開く。「見積依頼NO」に準備表の見積AのNO、状態チェックに「破棄」を指定して「検索」。対象の依頼NO・取引先名・サポートIDと、残る契約とのDB関連を準備表で確認する。 手順2：対象行の複数の「見積」列のうち「破棄」と表示されるリンクを押す。「見積を破棄します。よろしいですか？」の「OK」を押す。 手順3：使用中による破棄不可通知をOKで閉じ、同じ見積依頼NOで再検索する。「契約NO」リンクで関連1005Uも開いて契約・期間・機器を確認する。 手順4：DB担当者が見積と契約状態、関連件数・値を比較する。 | G40: ・破棄不可通知が出る。再検索の画面状態は準備時の「破棄」のまま。元見積契約時間と残る契約の状態・期間・機器を、この見積破棄操作で変更しない。 ・MCM_TM_KEIYAKUJIKAN.JOTAIとMCM_TK_KEIYAKU.JOTAIは処理前のまま。契約の期間・機器・単価・支払・添付の削除0件。 | H40: 確認「見積を破棄します。よろしいですか？」→OK。MSG_0025E「店舗への見積依頼 又は 取引先との契約として使用されている為、破棄する事が出来ません。」→OK。 | I40: OK | J40: 寺澤 | K40: 46311 | P40: =IF(M40<>"",M40,IF(I40<>"",I40,"未実施")) -> OK | Q40: 移行元：1003-21 契約済み見積を対象とする拒否。実機で未判定。 権限は1005Uではなく1002Uの作成権限。メッセージだけでなく両状態と関連データ不変を確認。 VB原本mcm_1003_v.sqlの106～108行は契約／解約状態の見積破棄文字をNULLとする。破棄済契約では見積破棄文字が残り、Serviceの契約存在ガードは状態を問わない。この条件で拒否とDB不変を確認する。有効契約そのものの拒否を検証するには、未契約で表示した一覧を保持し別セッションで契約登録後に旧リンクを押す競合シナリオが必要で、単独の既存行押下とは区別する。 元Excel行：40。実施区分：通常の準備操作＋DB・配備ビュー確認（契約存在ガード）。元の画面間フロー：1003U→1005U。
A41: INT01-32 | B41: 異常系 | C41: 過去支払がある契約の破棄拒否（通常契約） | D41: 1003U→3002U/1005U | E41: 【用意するもの】「取引先契約内容」の作成権限を持つユーザー。パック契約でない通常契約A。支払明細の最小年月が実施年月より前で、1003Uの右側「契約」列に「破棄」リンクが表示されるもの。 【準備】DB担当者が支払最小年月、元見積契約時間ID、契約ID、両状態と関連親子件数を記録する。実施月2026/10なら最小月2026/09以前。実際の送金済みという条件へ読み替えず、支払明細月で準備する。 【入力値】準備表に実際の番号・名称・日付・値を記入する。 【全ケース共通】試験専用の環境・データを使用。接続先と実行日／月を記録し、画面の識別番号（ID）・変更前情報を控える。DBの確認は担当者に読取だけを依頼し、自分で書き換えない。 | F41: 手順1：メニュー「取引先見積・契約検索」を開き、「契約NO」でAを検索する。契約NO、取引先名、サポートIDと状態を準備表と照合する。 手順2：右端の2つの「契約」列のうち右側の「破棄」リンクを押す。「契約を破棄します。よろしいですか？」の「OK」を押す。 手順3：支払による破棄不可通知をOKで閉じる。同じ契約NOで検索して状態を比較し、「契約NO」リンクから1005Uの期間・機器・添付を確認する。 手順4：DB担当者が元見積・契約の状態、期間・支払・機器・単価・添付の件数と値を比較する。 | G41: ・破棄不可通知が出る。契約は「破棄」にならず、元見積も「見積」へ戻らない。1005Uの期間・機器・添付が残る。 ・MCM_TK_KEIYAKU.JOTAIとMCM_TM_KEIYAKUJIKAN.JOTAIは処理前のまま。期間・支払親子・機器・単価・添付の削除0件、保存値不変。 | H41: 確認「契約を破棄します。よろしいですか？」→OK。MSG_0026E「取引先への支払が発生している為、破棄する事が出来ません。」→OK。 | I41: OK | J41: 寺澤 | K41: 46311 | P41: =IF(M41<>"",M41,IF(I41<>"",I41,"未実施")) -> OK | Q41: 移行元：1003-23 通常契約経路の拒否。パック経路のINT03-05とは別。実機で未判定。 パック経路はINT03-05で分担。当月のみの支払データを過去月条件として使わない。リンク非表示ならデータ準備・到達条件を確認する。 元Excel行：41。実施区分：通常＋DB担当者の読取確認。元の画面間フロー：1003U→3002U/1005U。
A43: 付録A：INT01-19の独立したチェック不足条件（開発者用）
A44: 通常UIでは、構成→明細→個体のチェックが連動する。B／Cを作るためのDB書換えは行わず、専用試験セッションの画面チェックだけを設定する。作成権限のないチェックを有効化しない。
A45: 1. 1003Uの未契約見積から1006U①→「次へ」で②を開き、試験対象の構成・明細・個体を少なくとも1組ONにする。採用見積の行だけが対象であることを確認する。
A46: 2. 開発者がF12のConsoleを開き、下のコードのpatternを「明細0」又は「個体0」に設定して実行する。画面でチェック不足を確認する。changeイベントは発生させず、UIの連動が補正する前の状態を作る。
A47: JavaScript
A48: const pattern = '明細0'; // 次条件では「個体0」に変更し、画面を開き直してから実行する
A49: const targets = pattern === '明細0' ? ['meisaiGrid'] : ['kotaiGrid'];
A50: for (const id of targets) {
A51: const table = document.getElementById(id);
A52: if (!table) throw new Error('MCM1006U②の対象表がありません');
A53: for (const box of table.querySelectorAll('input[type="checkbox"][name]')) {
...

Sheet INT02_審査承認
A1: MCM契・解約機能 結合テスト仕様書｜取引先契約の申請・審査・承認
A2: 実施前にE列を確認。登録確認はOK、取消ケースは取消。複数パターンは全て実施・期待一致ならOK、期待不一致ありならNG、NGなしで未実施・判断待ちが残る場合は保留。Q列にパターン別結果・実ID・証跡を追記し、既存の根拠は消さない。
A3: 単体13画面596件の表示・入力・単独判定は「単体との対応」へ分担。対象外は重複除外の設定で実行合格ではない。Q付きの期待・環境を確定してから追加判定を実施。
A4: 最終判定は再テスト結果を優先。「保留」集計は未実施も含む残件。合格率＝OK／実テスト件数。表示形式・ネイティブOfficeの動作は実行時に確認。
A6: テスト件数 | B6: =COUNTA(A10:A38) -> 29 | C6: 対象外件数 | D6: =COUNTIF(O10:O38,"対象外") -> 10 | E6: 実テスト件数 | F6: =B6-D6 -> 19 | G6: 完了件数OK | H6: =COUNTIF(O10:O38,"OK") -> 0 | I6: NG件数 | J6: =COUNTIF(O10:O38,"NG") -> 0 | K6: 保留 | L6: =MAX(0,F6-H6-J6) -> 19 | M6: 実施率 | N6: =IF(F6=0,0,(H6+J6)/F6) -> 0 | O6: 合格率 | P6: =IF(F6=0,0,H6/F6) -> 0
A8: 単体との重複を除いた結合テストケース
A9: 項番 | B9: 分類 | C9: テスト観点 | D9: 前提条件（ここを読んで準備する） | E9: 操作手順 | F9: 期待結果 | G9: 期待メッセージ | H9: テスト結果 | I9: 実施者 | J9: 実施日 | K9: 不具合内容 | L9: 再テスト結果 | M9: 再テスト実施者 | N9: 再テスト実施日 | O9: 最終判定 | P9: 備考／根拠
A10: INT02-01 | B10: 正常系 | C10: MCM1005U(取引先契約内容)→MCM1011U(審査・承認（取引先契約）)：申請した契約・期間・添付が、審査担当者の審査一覧に表示されること | D10: 【確認すること】 申請者が契約を申請すると、審査担当者の審査一覧(MCM1011U)に、その契約・期間・添付が「審査中」で表示され、DBの状態も審査中に更新されること。ほかの契約・期間・資料が巻き込まれないこと。 【前提】 ・使用ユーザー：2名。ユーザーA（申請者）とユーザーB（審査担当者）。AとBは、別のブラウザ、または別のログインで同時に使う ・保有権限：A＝取引先契約内容(MCM1005U)の更新作成権限。B＝審査・承認（取引先契約）(MCM1011U)で審査を行う権限 ・必要な登録済みデータ：専用の試験契約（1件） - 状態＝契約、承認状態＝作成中（申請前の状態） - 申請する期間（最新の現在期間、または未来の期間）に、作成中の添付が1件ある。その期間に承認済みの資料は置かない - 点検と支払は、「回数」がチェックした月の数以上で、支払の開始月にチェックがある - 契約期間は1年以内である ・事前に控える値：試験契約の契約NO、サポートID、取引先名、対象期間の開始日、時間、添付の資料名（ファイル名）。DB担当者に、契約ID・期間ID・添付IDと、申請前の保存値を読取で控えてもらう ・準備：Bの審査担当者としてログインしたセッションを別に用意し、Aの操作中もログアウトしない ・開始時の画面状態：A、Bとも、メニュー画面（Bはすでに審査・承認（取引先契約）が表示されていてもよい） | E10: 【操作】 1. [A] メニューから「取引先見積・契約検索」を選択し、MCM1003U(取引先見積・契約検索)を開く。 2. [A] 「契約NO」欄に試験契約の契約NOを入力する。他の入力欄は空欄のままにし、状態と承認状態のチェックは試験契約の状態（契約、作成中）を含めて、「検索」を押下する。 3. [A] 一覧で、契約NO・取引先名・サポートIDが試験契約と一致する行の「契約NO」リンクを押下する。MCM1005U(取引先契約内容)が開く。 4. [A] 開始日が控えた値の期間のタブを選択する。 5. [A] 期間のタブを選択したまま、画面右下の「申請」を押下する。登録の確認ダイアログ「登録を実施します。よろしいですか？」が表示された場合は「OK」を押下する。続けて、申請の確認ダイアログ「申請を実施します。よろしいですか？」で「OK」を押下する。表示された完了メッセージを控える。 6. [B] 審査・承認（取引先契約）(MCM1011U)を開く。表示されていない場合は、「閉じる」を押下してメニューへ戻り、「審査・承認（取引先契約）」を押下する。すでに表示されている場合は、その画面で検索条件を変更する。 7. [B] 「サポートID」欄に、試験契約のサポートIDを入力する。他の入力欄は空欄にする。「承認状態」は「審査中」だけにチェックを入れて、「検索」を押下する。 8. [B] 画面上段の「<< 申請 >>」の一覧で、契約NO・開始日・時間・取引先名・サポートIDが控えた値と一致する行を選択する。 9. [B] 選択した行の左端を押下し、画面下段の一覧に表示される「ファイル名」が、控えた資料名と一致することを確認する。このケースでは、行のチェックをONにせず、承認も差戻しもしない。 10. DB担当者に、控えた契約ID・期間ID・添付IDで、申請の前後の保存値を読取で比べてもらう。対象外の期間・資料・ほかの契約も、同じように比べてもらう。証拠の名前（画面キャプチャのファイル名など）を記録する。 【入力値】 ・契約NO＝試験契約の契約NO（手順2） ・サポートID＝試験契約のサポートID（手順7） ・承認状態（検索条件）＝「審査中」のみチェックを入れる（手順7） | F10: 【画面確認】 1. 審査担当者(B)のMCM1011U(審査・承認（取引先契約）)の「<< 申請 >>」の一覧に、試験契約の行が1件表示されること。 2. その行の承認状態が「審査中」で、契約NO・開始日・金額・取引先名・サポートIDが、申請者(A)が申請した内容と一致すること。 3. 行を選択すると、下段の「ファイル名」に、申請した資料名が表示されること。 4. ほかの契約・ほかの期間の資料が、この行の下段に表示されないこと。 【DB確認】 対象テーブル＝MCM_TK_KEIYAKU、MCM_TK_KIKAN、MCM_TK_TENPU、確認理由＝申請の結果、状態が審査中に更新され、対象外の期間・資料・契約が変わっていないことを確認するため。検索条件＝記録した契約ID・期間ID・添付ID、期待値＝次のとおり。 ・MCM_TK_KEIYAKU.SHONINJOTAI＝1（審査中）であること。 ・対象期間のMCM_TK_KIKAN.YUKO_FLG＝-1（申請中を表す値）であること。 ・対象の添付のMCM_TK_TENPU.SHONINJOTAI＝1（審査中）で、TK_KIKAN_IDが記録した期間IDであること。 ・ほかの期間・ほかの契約・ほかの添付の状態が、申請前のままであること。 | G10: 1. 表示タイミング＝申請者(A)が「申請」を押下した時（登録の確認ダイアログは、画面に変更があるときだけ先に表示される） 表示形式＝確認ダイアログ（OK/キャンセル） メッセージID＝MSG_0007G（登録の確認）、MSG_0120G（申請の確認） 表示文言＝「登録を実施します。よろしいですか？」、「申請を実施します。よろしいですか？」 作業者の操作＝「OK」を押下する 2. 表示タイミング＝申請の完了時 表示形式＝完了メッセージ メッセージID＝MSG_0121G 表示文言＝「申請を完了しました。」（Web版で「申請が完了しました。」と表示された場合は、VB版との差異として備考に記録する） 作業者の操作＝特になし | O10: =IF(L10<>"",L10,IF(H10<>"",H10,"未実施")) -> 未実施 | P10: 関連単体：1005-26, 1011-5 単体の表示・単独操作ではなく、期待結果の連携部分を追加判定。 根拠：R1005 / R1011 元Excel行：10。実施区分：通常操作＋DB読取。元フロー：1005U→1011U。
A11: INT02-02 | B11: 正常系 | C11: MCM1005U(取引先契約内容)→MCM1011U(審査・承認（取引先契約）)：「ロック解除」後に金額を変更して未保存のまま申請すると、変更後の金額が審査対象の金額になること | D11: 【確認すること】 申請者が金額と備考を変更し、「登録」を押さずに「申請」を押したとき、保存済みの金額（100,000円）ではなく、変更後の金額（99,000円）で審査担当者の画面（MCM1011U）に表示されること。DBにも変更後の金額が保存されること。 【前提】 ・使用ユーザー：2名。ユーザーA（申請者）とユーザーB（審査担当者）。AとBは、別のブラウザ、または別のログインで同時に使う ・保有権限： - A＝担当者マスタの保守フラグがONで、取引先契約内容(MCM1005U)の更新権限を持つユーザー(Web版では、この2条件を満たす場合だけ「ロック解除」ボタンが表示される)（普通の作成ユーザーでは金額欄が読取専用なので、このケースは実施できない） - B＝審査・承認（取引先契約）(MCM1011U)で審査を行う権限を持つユーザー。Bの「契約の審査上限金額」は99,000円に設定されていること ・必要な登録済みデータ：専用の試験契約（1件） - 状態＝契約、承認状態＝作成中（申請前の状態） - 申請する期間（最新の現在期間、または未来の期間）に、作成中の添付が1件ある。その期間に承認済みの資料は置かない - 点検と支払は、「回数」がチェックした月の数以上で、支払の開始月にチェックがある - 契約期間は1年以内である - 申請する期間の金額が、「小計」＝100,000円、「出精値引き」＝0円、「合計」＝100,000円で保存済みである - 上段の「備考」が「INT02-02前」で保存済みである ・事前に控える値：試験契約の契約NO、サポートID、取引先名、対象期間の開始日、時間、添付の資料名（ファイル名）。DB担当者に、契約ID・期間ID・添付IDと、申請前の保存値を読取で控えてもらう ・準備：Bの審査担当者としてログインしたセッションを別に用意し、Aの操作中もログアウトしない ・開始時の画面状態：A、Bとも、メニュー画面（Bはすでに審査・承認（取引先契約）が表示されていてもよい） | E11: 【操作】 1. [A] メニューから「取引先見積・契約検索」を選択し、MCM1003U(取引先見積・契約検索)を開く。 2. [A] 「契約NO」欄に試験契約の契約NOを入力する。他の入力欄は空欄のままにし、状態と承認状態のチェックは試験契約の状態（契約、作成中）を含めて、「検索」を押下する。 3. [A] 一覧で、契約NO・取引先名・サポートIDが試験契約と一致する行の「契約NO」リンクを押下する。MCM1005U(取引先契約内容)が開く。 4. [A] 開始日が控えた値の期間のタブを選択する。 5. [A] 画面右下の「ロック解除」を押下する。「管理者用ロックを解除しました。最新の登録内容を表示します。」の通知を確認する。画面が再表示されたら、手順4と同じ期間のタブを選び直す。 6. [A] 次の3か所を入力する。「小計」は100,000円のまま変更しない。入力後は「登録」を押下しない。 - 画面上段右の「備考」に「INT02-02後」と入力する - 期間タブ内の「出精値引き」に1,000と入力する - 「出精値引き」の直下の「合計」に99,000と入力する（その上の「≪標準価格≫」の「合計」ではない） 7. [A] 期間のタブを選択したまま、画面右下の「申請」を押下する。登録の確認ダイアログ「登録を実施します。よろしいですか？」が表示された場合は「OK」を押下する。続けて、申請の確認ダイアログ「申請を実施します。よろしいですか？」で「OK」を押下する。表示された完了メッセージを控える。 8. [B] 審査・承認（取引先契約）(MCM1011U)を開く。表示されていない場合は、「閉じる」を押下してメニューへ戻り、「審査・承認（取引先契約）」を押下する。すでに表示されている場合は、その画面で検索条件を変更する。 9. [B] 「サポートID」欄に、試験契約のサポートIDを入力する。他の入力欄は空欄にする。「承認状態」は「審査中」だけにチェックを入れて、「検索」を押下する。 10. [B] 画面上段の「<< 申請 >>」の一覧で、契約NO・開始日・時間・取引先名・サポートIDが控えた値と一致する行を探す。行の左端（▶の部分）を押下して選択する。契約NOのリンクは押下しない（MCM1005Uが別タブで開くため）。 11. [B] 同じ行の「金額」と、行の左端のチェックボックスの活性状態を記録する。画面下段「<< 添付 >>」の「ファイル名」が、控えた資料名と一致することも確認する。このケースでは、「承認」「差戻し」は押下しない。 12. [A] 1005Uが開いたままの場合は、保存せずに「閉じる」を押下して戻る。メニューにいる場合は、「取引先見積・契約検索」を押下してMCM1003Uを開く。「契約NO」に試験契約の契約NOを入力し、他の入力欄は空欄にして、「承認状態」は今回の操作後の状態（審査中）を含めて「検索」を押下する。対象行の「契約NO」リンクを押下し、MCM1005Uを開く。 13. [A] 手順4と同じ期間のタブを選択し、次の内容を記録する。 - 上段の「承認状態」 - 上段右の「備考」 - 期間タブ内の「小計」「出精値引き」「合計」 - 「≪添付資料≫」の対象ファイル名 14. DB担当者に、控えた契約ID・期間ID・添付IDで、申請の前後の保存値を読取で比べてもらう。対象外の期間・資料・ほかの契約も、同じように比べてもらう。証拠の名前（画面キャプチャのファイル名など）を記録する。 【入力値】 ・備考（上段右）＝INT02-02後（変更前の保存値は INT02-02前） ・出精値引き＝1,000（変更前は0） ・合計（出精値引きの直下）＝99,000（変更前は100,000） ・小計＝100,000（変更しない） ・サポートID＝試験契約のサポートID（手順9） ・承認状態（検索条件）＝「審査中」のみチェックを入れる（手順9） | F11: 【画面確認】 1. 審査担当者(B)のMCM1011Uの「<< 申請 >>」の一覧で、試験契約の行の「金額」が99,000円（画面には「¥99,000」と表示）であること。変更前の100,000円ではないこと。 2. その行の承認状態が「審査中」で、行の左端のチェックボックスが活性であること（金額が審査上限99,000円を超えていないため、上限超過の扱いにならない）。 3. 下段「<< 添付 >>」の「ファイル名」に、申請した資料名が表示されること。 4. 申請者(A)がMCM1005Uを開き直すと、上段右の「備考」が「INT02-02後」、「出精値引き」が1,000円、「出精値引き」の直下の「合計」が99,000円、「小計」が100,000円であること。上段の「承認状態」が「審査中」であること。 【DB確認】 対象テーブル＝MCM_TK_KEIYAKU、MCM_TK_KIKAN、MCM_TK_TENPU、確認理由＝未保存の変更が申請と同時に保存され、審査対象の金額が変更後の値になっていることを確認するため。検索条件＝記録した契約ID・期間ID・添付ID、期待値＝次のとおり。 ・申請した期間のMCM_TK_KIKAN.SIKIRIGOKEI_KIN＝99,000、SYUSSEINEBIKI_KIN＝1,000であること（保存済みだった100,000を審査額に使っていないこと）。 ・MCM_TK_KEIYAKU.BIKO＝「INT02-02後」に更新されていること。 ・MCM_TK_KEIYAKU.SHONINJOTAI＝1（審査中）、対象期間のMCM_TK_KIKAN.YUKO_FLG＝-1（申請中を表す値）、対象の添付のMCM_TK_TENPU.SHONINJOTAI＝1（審査中）であること。 ・ほかの期間・ほかの契約・ほかの添付の状態と金額が、申請前のままであること。 | G11: 1. 表示タイミング＝申請者(A)が「ロック解除」を押下した時 表示形式＝通知 メッセージID＝－（VB版は未定義） 表示文言＝VB版の通知の有無は要確認。Web版は「管理者用ロックを解除しました。最新の登録内容を表示します。」を表示する。判定は、金額欄が入力できる状態になることで行い、通知の有無・文言の一致は求めない 作業者の操作＝特になし 2. 表示タイミング＝申請者(A)が「申請」を押下した時（登録の確認ダイアログは、画面に変更があるときだけ先に表示される） 表示形式＝確認ダイアログ（OK/キャンセル） メッセージID＝MSG_0007G（登録の確認）、MSG_0120G（申請の確認） 表示文言＝「登録を実施します。よろしいですか？」、「申請を実施します。よろしいですか？」 作業者の操作＝「OK」を押下する 3. 表示タイミング＝申請の完了時 表示形式＝完了メッセージ メッセージID＝MSG_0121G 表示文言＝「申請を完了しました。」（Web版で「申請が完了しました。」と表示された場合は、VB版との差異として備考に記録する） 作業者の操作＝特になし | O11: =IF(L11<>"",L11,IF(H11<>"",H11,"未実施")) -> 未実施 | P11: 関連単体：1005-26, 1011-9, 1011-10 単体の表示・単独操作ではなく、期待結果の連携部分を追加判定。 根拠：R1005 / R1011 ロック解除権限をブラウザーで付与しない。審査可否の境界は15、ここでは未保存金額が申請対象へ渡ることを判定する。 元Excel行：11。実施区分：管理者権限による画面操作＋DB読取。元フロー：1005U→1011U。
A12: INT02-03 | B12: 正常系 | C12: MCM1011U（審査・承認（取引先契約））→MCM1005U（取引先契約内容）：一覧の「契約NO」リンクから、対象の契約・期間・添付を参照できること | D12: 【確認すること】 審査一覧の「契約NO」リンクから、その契約が別タブで開くこと。対象期間のタブを選ぶと、審査一覧と同じ資料が表示され、参照用の表示になっていること。 【前提】 ・使用ユーザー：ユーザーB（審査担当者） ・保有権限：MCM1011Uの利用権限と、MCM1005Uの参照または作成権限 ・必要な登録済みデータ：審査中の試験契約1件。開始日と添付資料が異なる期間を2つ以上持ち、対象期間には審査中の添付があること ・事前に控える値：契約NO、取引先名、納入先名、サポートID、対象期間の開始日、添付のファイル名 ・準備：対象期間と添付資料を準備担当者に確認しておく ・開始時の画面状態：Bはメニュー画面 | E12: 【操作】 1. [B] メニューの「審査・承認（取引先契約）」を押下し、MCM1011Uを開く。 2. 「サポートID」に試験契約のサポートIDを入力する。他の入力欄は空欄、「承認状態」は「審査中」だけにチェックを入れて「検索」を押下する。 3. 契約NO・取引先名・開始日が控えた値と一致する行を探す。行の左端（▶の部分）を押下し、下段「<< 添付 >>」のファイル名を確認する。処理用のチェックボックスはONにしない。 4. 同じ行の「契約NO」リンクを押下する。別タブで開いたMCM1005Uの「契約NO」「取引先」「納入先」を、控えた値と照合する。 5. 控えた開始日と同じ期間のタブを選択し、「≪添付資料≫」のファイル名を確認する。期間タブは自動選択されるとは限らないため、自分で選択する。 6. 上段の「契約NO」が入力できないことと、画面右下の「申請」「契約発行」が押せないことを確認する。更新操作は行わない。 7. ブラウザーで元のMCM1011Uのタブへ戻り、検索条件・選択行・下段のファイル名が残っていることを確認する。 【入力値】 ・サポートID＝試験契約のサポートID（手順2） ・承認状態＝「審査中」のみON（手順2） ・期間タブ＝控えた開始日の期間（手順5） | F12: 【画面確認】 1. 「契約NO」リンクから、別タブで対象契約のMCM1005Uが開き、契約NO・取引先・納入先が控えた値と一致すること。 2. 対象期間のタブを選ぶと、「≪添付資料≫」に審査一覧の下段と同じファイル名が表示されること。 3. 「契約NO」が読取専用で、「申請」「契約発行」が非活性であること。 4. 元のMCM1011Uへ戻ると、検索条件・選択行・下段のファイル名が維持されていること。 【DB確認】 実施不要。理由＝このケースは、リンク先の契約・期間・添付と参照表示を画面で確認する。 | G12: 表示タイミング＝メッセージは表示されない 表示形式＝－ メッセージID＝－ 表示文言＝－ 作業者の操作＝特になし | O12: =IF(L12<>"",L12,IF(H12<>"",H12,"未実施")) -> 未実施 | P12: 関連単体：1011-14 根拠：R1011／R1005 リンクは契約IDを渡し、期間IDは渡さないため、対象期間のタブは実施者が選択する。
A13: INT02-04 | B13: 正常系 | C13: MCM1011U(審査・承認（取引先契約）)→MCM1005U(取引先契約内容)：審査（承認ボタン）の完了が、契約・添付・審査者・審査日に反映され、申請中のまま「承認中」になること | D13: 【確認すること】 審査担当者が「承認」を押すと、契約と対象の添付が「審査中」から「承認中」に進み、審査者と審査日が記録されること。期間の有効値は申請中のままで、ほかの期間・資料・契約が変わらないこと。 【前提】 ・使用ユーザー：ユーザーB（審査担当者）とユーザーA（確認用。申請内容を後で画面から確認する） ・保有権限： - B＝審査・承認（取引先契約）(MCM1011U)で、審査を行う資格と作成権限を持つ。契約の審査上限金額が、対象の「金額」以上である。担当者マスタにBの氏名が設定されている - A＝取引先契約内容(MCM1005U)の参照または作成の権限 ・必要な登録済みデータ：専用の試験契約（1件） - 状態＝契約、承認状態＝審査中。対象の添付も審査中。対象期間の有効値＝-1（申請中） - 最新の現在期間、または未来の期間を使用する - 点検と支払は、「回数」がチェックした月の数以上で、支払の開始月にチェックがある - 契約期間は1年以内である - 添付がExcelファイル（xls、xlsx、xlsm）の場合は、審査印の図形がそろった原紙を使う ・事前に控える値：試験契約の契約NO、サポートID、取引先名、対象期間の開始日、時間、金額、添付の資料名。審査者と審査日の処理前の値と、Bの氏名。DB担当者に、契約ID・期間ID・添付IDと、処理前の保存値を読取で控えてもらう ・準備：Bの審査担当者としてログインしたセッションを別に用意し、Aの操作中もログアウトしない ・開始時の画面状態：A、Bとも、メニュー画面（Bはすでに審査・承認（取引先契約）が表示されていてもよい） | E13: 【操作】 1. [B] 審査・承認（取引先契約）(MCM1011U)を開く。表示されていない場合は、「閉じる」を押下してメニューへ戻り、「審査・承認（取引先契約）」を押下する。すでに表示されている場合は、その画面で検索条件を変更する。「サポートID」欄に試験契約のサポートIDを入力する。他の入力欄は空欄にする。「承認状態」は「審査中」だけにチェックを入れて、「検索」を押下する。 2. [B] 画面上段の「<< 申請 >>」の一覧で、契約NO・開始日・時間・取引先名・サポートIDが控えた値と一致する行を探す。行の左端（▶の部分）を押下して選択し、画面下段「<< 添付 >>」の「ファイル名」が控えた資料名と一致することを確認する。処理対象の行だけ、左から2列目のチェックボックスをONにする。 3. [B] 「承認」を押下する。確認ダイアログ「審査・承認処理を実施します。よろしいですか？」で「OK」を押下する。表示された完了メッセージを控える。 4. [B] 手順1と同じ方法で、MCM1011Uを検索し直す。「サポートID」は同じ値、他の入力欄は空欄、「承認状態」は「承認中」だけにチェックを入れて「検索」を押下する。 5. [B] 「<< 申請 >>」の一覧で、手順2と同じ条件の行を探し、行の左端を押下して選択する。下段の「ファイル名」を確認する。チェックボックスはONにしない。同じ行の「審査日」「審査者」「金額」を記録する。 6. [A] メニューから「取引先見積・契約検索」を選択し、MCM1003U(取引先見積・契約検索)を開く。「契約NO」に試験契約の契約NOを入力し、他の入力欄は空欄にして、「承認状態」は今回の操作後の状態（承認中）を含めて「検索」を押下する。対象行の「契約NO」リンクを押下し、MCM1005U(取引先契約内容)を開く。 7. [A] 開始日が控えた値の期間のタブを選択する。次の内容を記録する。 - 上段の「承認状態」 - 期間タブの名前の末尾（「(申請中)」などの表示） - 期間タブ内の機器、「小計」「出精値引き」「合計」 - 「≪添付資料≫」の対象ファイルの「ファイル名」と「承認状態」 なお、「登録」「申請」などは押下しない。 8. DB担当者に、控えた契約ID・期間ID・添付IDで、処理の前後の保存値を読取で比べてもらう。対象外の期間・資料・ほかの契約も、同じように比べてもらう。証拠の名前（画面キャプチャのファイル名など）を記録する。 【入力値】 ・サポートID＝試験契約のサポートID（手順1、手順4） ・承認状態（検索条件）＝手順1は「審査中」のみ、手順4は「承認中」のみチェックを入れる ・チェックボックス＝対象の1行だけON（手順2） | F13: 【画面確認】 1. 手順4の検索結果（承認中）に、試験契約の行が1件表示され、承認状態が「承認中」であること。 2. その行の「審査者」がBの氏名、「審査日」が実施日であること。「金額」と下段の「ファイル名」が、控えた準備値と一致すること。 3. 申請者側のMCM1005Uで、上段の「承認状態」が「承認中」、対象のファイルの「承認状態」が「承認中」であること。 4. 対象期間のタブの名前の末尾に「(申請中)」が表示されたままであること。金額・機器は準備値のままで、別の期間の資料や金額が混ざっていないこと。 【DB確認】 対象テーブル＝MCM_TK_KEIYAKU、MCM_TK_KIKAN、MCM_TK_TENPU、確認理由＝審査の結果、契約と添付の状態だけが進み、審査者と審査日が正しく記録され、対象外のデータが変わっていないことを確認するため。検索条件＝記録した契約ID・期間ID・添付ID、期待値＝次のとおり。 ・契約と対象の添付の両方で、SHONINJOTAI＝2（承認中）であること。 ・SHINSA_BY＝Bの氏名であること。SHINSA_DTが、処理を始めた時刻から完了した時刻までの範囲にあること。 ・対象期間のYUKO_FLGが-1のままであること。 ・ほかの期間・承認済みの資料・ほかの契約の状態が、処理前のままであること。 | G13: 表示タイミング＝審査担当者(B)が「承認」を押下した時、およびその完了時 表示形式＝確認ダイアログ（OK/キャンセル）、完了メッセージ メッセージID＝MSG_0094G（確認）、MSG_0090G（完了） 表示文言＝「審査・承認処理を実施します。よろしいですか？」、「審査・承認を完了しました。」（表示文言のみの確認は単体に委ねる） 作業者の操作＝確認ダイアログで「OK」を押下する | O13: =IF(L13<>"",L13,IF(H13<>"",H13,"未実施")) -> 未実施 | P13: 関連単体：1011-21, 1005-4, 1005-5 単体の表示・単独操作ではなく、期待結果の連携部分を追加判定。 根拠：R1011 / R1005 元Excel行：13。実施区分：通常操作＋DB読取。元フロー：1011U→1005U。
